Workbook
Name ПЛАНОВЫЕ: [1]Лист1!$J$23:$J$23
Name ПРОСТОИ: [1]Лист1!$J$9:$J$14
Name ПРОСТОЙ: [1]Лист1!$J$23:$J$23

Sheet СВОД
B1: Линия №6
B2: Смена | C2: Показатель | E2: Ед. изм. | F2: ИТОГО | G2: 1 | H2: 2 | I2: 3 | J2: 4 | K2: 5 | L2: 6 | M2: 7 | N2: 8 | O2: 9 | P2: 10 | Q2: 11 | R2: 12 | S2: 13 | T2: 14 | U2: 15 | V2: 16 | W2: 17 | X2: 18 | Y2: 19 | Z2: 20 | AA2: 21 | AB2: 22 | AC2: 23 | AD2: 24 | AE2: 25 | AF2: 26 | AG2: 27 | AH2: 28 | AI2: 29 | AJ2: 30 | AK2: 31
B3: ДЕНЬ | C3: Факт выпуска | E3: шт | F3: =SUM(G3:AK3) -> #REF! | G3: =SUM('1'!$K$21:$K$32) -> 0 | H3: =SUM('2'!$K$21:$K$32) -> 0 | I3: =SUM('3'!$K$21:$K$32) -> 0 | J3: =SUM('4'!$K$21:$K$32) -> 0 | K3: =SUM('5'!$K$21:$K$32) -> 0 | L3: =SUM('6'!$K$21:$K$32) -> 0 | M3: =SUM('7'!$K$21:$K$32) -> 0 | N3: =SUM('8'!$K$21:$K$32) -> 1735 | O3: =SUM('9'!$K$21:$K$32) -> 915 | P3: =SUM('10'!$K$21:$K$32) -> 0 | Q3: =SUM('11'!$K$21:$K$32) -> 0 | R3: =SUM('12'!$K$21:$K$32) -> 0 | S3: =SUM('13'!$K$21:$K$32) -> 3617 | T3: =SUM('14'!$K$21:$K$32) -> 875 | U3: =SUM('15'!$K$21:$K$32) -> 0 | V3: =SUM('16'!$K$21:$K$32) -> 0 | W3: =SUM('17'!$K$21:$K$32) -> 0 | X3: =SUM('18'!$K$21:$K$32) -> 0 | Y3: =SUM('19'!$K$21:$K$32) -> 0 | Z3: =SUM('20'!$K$21:$K$32) -> 0 | AA3: =SUM('21'!$K$21:$K$32) -> 0 | AB3: =SUM(#REF!) -> #REF! | AC3: =SUM(#REF!) -> #REF! | AD3: =SUM(#REF!) -> #REF! | AE3: =SUM(#REF!) -> #REF! | AF3: =SUM(#REF!) -> #REF! | AG3: =SUM(#REF!) -> #REF! | AH3: =SUM(#REF!) -> #REF! | AI3: =SUM(#REF!) -> #REF! | ... AK3: =SUM(#REF!) -> #REF!
C4: Продуктивное время | E4: мин | F4: =SUM(G4:AK4) -> #REF! | G4: =SUM('1'!$F$21:$F$32) -> 0 | H4: =SUM('2'!$F$21:$F$32) -> 0 | I4: =SUM('3'!$F$21:$F$32) -> 0 | J4: =SUM('4'!$F$21:$F$32) -> 0 | K4: =SUM('5'!$F$21:$F$32) -> 0 | L4: =SUM('6'!$F$21:$F$32) -> 0 | M4: =SUM('7'!$F$21:$F$32) -> 0 | N4: =SUM('8'!$F$21:$F$32) -> 160.15385 | O4: =SUM('9'!$F$21:$F$32) -> 84.461538 | P4: =SUM('10'!$F$21:$F$32) -> 0 | Q4: =SUM('11'!$F$21:$F$32) -> 0 | R4: =SUM('12'!$F$21:$F$32) -> 0 | S4: =SUM('13'!$F$21:$F$32) -> 482.26667 | T4: =SUM('14'!$F$21:$F$32) -> 116.66667 | U4: =SUM('15'!$F$21:$F$32) -> 0 | V4: =SUM('16'!$F$21:$F$32) -> 0 | W4: =SUM('17'!$F$21:$F$32) -> 0 | X4: =SUM('18'!$F$21:$F$32) -> 0 | Y4: =SUM('19'!$F$21:$F$32) -> 0 | Z4: =SUM('20'!$F$21:$F$32) -> 0 | AA4: =SUM('21'!$F$21:$F$32) -> 0 | AB4: =SUM(#REF!) -> #REF! | AC4: =SUM(#REF!) -> #REF! | AD4: =SUM(#REF!) -> #REF! | AE4: =SUM(#REF!) -> #REF! | AF4: =SUM(#REF!) -> #REF! | AG4: =SUM(#REF!) -> #REF! | AH4: =SUM(#REF!) -> #REF! | AI4: =SUM(#REF!) -> #REF! | ... AK4: =SUM(#REF!) -> #REF!
C5: Факт время | E5: мин | F5: =SUM(G5:AK5) -> #REF! | G5: =SUM('1'!$D$21:$D$32) -> 0 | H5: =SUM('2'!$D$21:$D$32) -> 0 | I5: =SUM('3'!$D$21:$D$32) -> 0 | J5: =SUM('4'!$D$21:$D$32) -> 0 | K5: =SUM('5'!$D$21:$D$32) -> 0 | L5: =SUM('6'!$D$21:$D$32) -> 0 | M5: =SUM('7'!$D$21:$D$32) -> 0 | N5: =SUM('8'!$D$21:$D$32) -> 600 | O5: =SUM('9'!$D$21:$D$32) -> 300 | P5: =SUM('10'!$D$21:$D$32) -> 0 | Q5: =SUM('11'!$D$21:$D$32) -> 0 | R5: =SUM('12'!$D$21:$D$32) -> 0 | S5: =SUM('13'!$D$21:$D$32) -> 720 | T5: =SUM('14'!$D$21:$D$32) -> 300 | U5: =SUM('15'!$D$21:$D$32) -> 0 | V5: =SUM('16'!$D$21:$D$32) -> 0 | W5: =SUM('17'!$D$21:$D$32) -> 0 | X5: =SUM('18'!$D$21:$D$32) -> 0 | Y5: =SUM('19'!$D$21:$D$32) -> 0 | Z5: =SUM('20'!$D$21:$D$32) -> 0 | AA5: =SUM('21'!$D$21:$D$32) -> 0 | AB5: =SUM(#REF!) -> #REF! | AC5: =SUM(#REF!) -> #REF! | AD5: =SUM(#REF!) -> #REF! | AE5: =SUM(#REF!) -> #REF! | AF5: =SUM(#REF!) -> #REF! | AG5: =SUM(#REF!) -> #REF! | AH5: =SUM(#REF!) -> #REF! | AI5: =SUM(#REF!) -> #REF! | ... AK5: =SUM(#REF!) -> #REF!
C7: ПРОСТОИ | D7: ПЛАНОВЫЕ | E7: мин | F7: =SUM(G7:AK7) -> #REF! | G7: ='1'!$V19 -> 0 | H7: ='2'!$V19 -> 0 | I7: ='3'!$V19 -> 0 | J7: ='4'!$V19 -> 0 | K7: ='5'!$V19 -> 0 | L7: ='6'!$V19 -> 0 | M7: ='7'!$V19 -> 0 | N7: ='8'!$V19 -> 0 | O7: ='9'!$V19 -> 20 | P7: ='10'!$V19 -> 0 | Q7: ='11'!$V19 -> 0 | R7: ='12'!$V19 -> 0 | S7: ='13'!$V19 -> 0 | T7: ='14'!$V19 -> 0 | U7: ='15'!$V19 -> 0 | V7: ='16'!$V19 -> 0 | W7: ='17'!$V19 -> 0 | X7: ='18'!$V19 -> 0 | Y7: ='19'!$V19 -> 0 | Z7: ='20'!$V19 -> 0 | AA7: ='21'!$V19 -> 0 | AB7: =#REF! -> #REF! | AC7: =#REF! -> #REF! | AD7: =#REF! -> #REF! | AE7: =#REF! -> #REF! | AF7: =#REF! -> #REF! | AG7: =#REF! -> #REF! | AH7: =#REF! -> #REF! | AI7: =#REF! -> #REF! | ... AK7: =#REF! -> #REF!
D8: ПРОИЗВОДСТВЕННЫЕ | E8: мин | F8: =SUM(G8:AK8) -> #REF! | G8: ='1'!$V20 -> 0 | H8: ='2'!$V20 -> 0 | I8: ='3'!$V20 -> 0 | J8: ='4'!$V20 -> 0 | K8: ='5'!$V20 -> 0 | L8: ='6'!$V20 -> 0 | M8: ='7'!$V20 -> 0 | N8: ='8'!$V20 -> 0 | O8: ='9'!$V20 -> 0 | P8: ='10'!$V20 -> 0 | Q8: ='11'!$V20 -> 0 | R8: ='12'!$V20 -> 0 | S8: ='13'!$V20 -> 0 | T8: ='14'!$V20 -> 0 | U8: ='15'!$V20 -> 0 | V8: ='16'!$V20 -> 0 | W8: ='17'!$V20 -> 0 | X8: ='18'!$V20 -> 0 | Y8: ='19'!$V20 -> 0 | Z8: ='20'!$V20 -> 0 | AA8: ='21'!$V20 -> 0 | AB8: =#REF! -> #REF! | AC8: =#REF! -> #REF! | AD8: =#REF! -> #REF! | AE8: =#REF! -> #REF! | AF8: =#REF! -> #REF! | AG8: =#REF! -> #REF! | AH8: =#REF! -> #REF! | AI8: =#REF! -> #REF! | ... AK8: =#REF! -> #REF!
D9: ТЕХНИЧЕСКИЕ | E9: мин | F9: =SUM(G9:AK9) -> #REF! | G9: ='1'!$V21 -> 0 | H9: ='2'!$V21 -> 0 | I9: ='3'!$V21 -> 0 | J9: ='4'!$V21 -> 0 | K9: ='5'!$V21 -> 0 | L9: ='6'!$V21 -> 0 | M9: ='7'!$V21 -> 0 | N9: ='8'!$V21 -> 441 | O9: ='9'!$V21 -> 220 | P9: ='10'!$V21 -> 0 | Q9: ='11'!$V21 -> 0 | R9: ='12'!$V21 -> 0 | S9: ='13'!$V21 -> 232 | T9: ='14'!$V21 -> 136 | U9: ='15'!$V21 -> 0 | V9: ='16'!$V21 -> 0 | W9: ='17'!$V21 -> 0 | X9: ='18'!$V21 -> 0 | Y9: ='19'!$V21 -> 0 | Z9: ='20'!$V21 -> 0 | AA9: ='21'!$V21 -> 0 | AB9: =#REF! -> #REF! | AC9: =#REF! -> #REF! | AD9: =#REF! -> #REF! | AE9: =#REF! -> #REF! | AF9: =#REF! -> #REF! | AG9: =#REF! -> #REF! | AH9: =#REF! -> #REF! | AI9: =#REF! -> #REF! | ... AK9: =#REF! -> #REF!
D10: ТЕХНОЛОГИЧЕСКИЕ | E10: мин | F10: =SUM(G10:AK10) -> #REF! | G10: ='1'!$V22 -> 0 | H10: ='2'!$V22 -> 0 | I10: ='3'!$V22 -> 0 | J10: ='4'!$V22 -> 0 | K10: ='5'!$V22 -> 0 | L10: ='6'!$V22 -> 0 | M10: ='7'!$V22 -> 0 | N10: ='8'!$V22 -> 0 | O10: ='9'!$V22 -> 0 | P10: ='10'!$V22 -> 0 | Q10: ='11'!$V22 -> 0 | R10: ='12'!$V22 -> 0 | S10: ='13'!$V22 -> 0 | T10: ='14'!$V22 -> 0 | U10: ='15'!$V22 -> 0 | V10: ='16'!$V22 -> 0 | W10: ='17'!$V22 -> 0 | X10: ='18'!$V22 -> 0 | Y10: ='19'!$V22 -> 0 | Z10: ='20'!$V22 -> 0 | AA10: ='21'!$V22 -> 0 | AB10: =#REF! -> #REF! | AC10: =#REF! -> #REF! | AD10: =#REF! -> #REF! | AE10: =#REF! -> #REF! | AF10: =#REF! -> #REF! | AG10: =#REF! -> #REF! | AH10: =#REF! -> #REF! | AI10: =#REF! -> #REF! | ... AK10: =#REF! -> #REF!
D11: ЛАБОРАТОРНЫЕ | E11: мин | F11: =SUM(G11:AK11) -> #REF! | G11: ='1'!$V23 -> 0 | H11: ='2'!$V23 -> 0 | I11: ='3'!$V23 -> 0 | J11: ='4'!$V23 -> 0 | K11: ='5'!$V23 -> 0 | L11: ='6'!$V23 -> 0 | M11: ='7'!$V23 -> 0 | N11: ='8'!$V23 -> 0 | O11: ='9'!$V23 -> 0 | P11: ='10'!$V23 -> 0 | Q11: ='11'!$V23 -> 0 | R11: ='12'!$V23 -> 0 | S11: ='13'!$V23 -> 0 | T11: ='14'!$V23 -> 0 | U11: ='15'!$V23 -> 0 | V11: ='16'!$V23 -> 0 | W11: ='17'!$V23 -> 0 | X11: ='18'!$V23 -> 0 | Y11: ='19'!$V23 -> 0 | Z11: ='20'!$V23 -> 0 | AA11: ='21'!$V23 -> 0 | AB11: =#REF! -> #REF! | AC11: =#REF! -> #REF! | AD11: =#REF! -> #REF! | AE11: =#REF! -> #REF! | AF11: =#REF! -> #REF! | AG11: =#REF! -> #REF! | AH11: =#REF! -> #REF! | AI11: =#REF! -> #REF! | ... AK11: =#REF! -> #REF!
D12: СЫРЬЕВЫЕ | E12: мин | F12: =SUM(G12:AK12) -> #REF! | G12: ='1'!$V24 -> 0 | H12: ='2'!$V24 -> 0 | I12: ='3'!$V24 -> 0 | J12: ='4'!$V24 -> 0 | K12: ='5'!$V24 -> 0 | L12: ='6'!$V24 -> 0 | M12: ='7'!$V24 -> 0 | N12: ='8'!$V24 -> 0 | O12: ='9'!$V24 -> 0 | P12: ='10'!$V24 -> 0 | Q12: ='11'!$V24 -> 0 | R12: ='12'!$V24 -> 0 | S12: ='13'!$V24 -> 0 | T12: ='14'!$V24 -> 0 | U12: ='15'!$V24 -> 0 | V12: ='16'!$V24 -> 0 | W12: ='17'!$V24 -> 0 | X12: ='18'!$V24 -> 0 | Y12: ='19'!$V24 -> 0 | Z12: ='20'!$V24 -> 0 | AA12: ='21'!$V24 -> 0 | AB12: =#REF! -> #REF! | AC12: =#REF! -> #REF! | AD12: =#REF! -> #REF! | AE12: =#REF! -> #REF! | AF12: =#REF! -> #REF! | AG12: =#REF! -> #REF! | AH12: =#REF! -> #REF! | AI12: =#REF! -> #REF! | ... AK12: =#REF! -> #REF!
D13: ЛОГИСТИЧЕСКИЕ | E13: мин | F13: =SUM(G13:AK13) -> #REF! | G13: ='1'!$V25 -> 0 | H13: ='2'!$V25 -> 0 | I13: ='3'!$V25 -> 0 | J13: ='4'!$V25 -> 0 | K13: ='5'!$V25 -> 0 | L13: ='6'!$V25 -> 0 | M13: ='7'!$V25 -> 0 | N13: ='8'!$V25 -> 0 | O13: ='9'!$V25 -> 0 | P13: ='10'!$V25 -> 0 | Q13: ='11'!$V25 -> 0 | R13: ='12'!$V25 -> 0 | S13: ='13'!$V25 -> 0 | T13: ='14'!$V25 -> 0 | U13: ='15'!$V25 -> 0 | V13: ='16'!$V25 -> 0 | W13: ='17'!$V25 -> 0 | X13: ='18'!$V25 -> 0 | Y13: ='19'!$V25 -> 0 | Z13: ='20'!$V25 -> 0 | AA13: ='21'!$V25 -> 0 | AB13: =#REF! -> #REF! | AC13: =#REF! -> #REF! | AD13: =#REF! -> #REF! | AE13: =#REF! -> #REF! | AF13: =#REF! -> #REF! | AG13: =#REF! -> #REF! | AH13: =#REF! -> #REF! | AI13: =#REF! -> #REF! | ... AK13: =#REF! -> #REF!
D14: ОБЩЕЗАВОДСКИЕ | E14: мин | F14: =SUM(G14:AK14) -> #REF! | G14: ='1'!$V26 -> 0 | H14: ='2'!$V26 -> 0 | I14: ='3'!$V26 -> 0 | J14: ='4'!$V26 -> 0 | K14: ='5'!$V26 -> 0 | L14: ='6'!$V26 -> 0 | M14: ='7'!$V26 -> 0 | N14: ='8'!$V26 -> 0 | O14: ='9'!$V26 -> 0 | P14: ='10'!$V26 -> 0 | Q14: ='11'!$V26 -> 0 | R14: ='12'!$V26 -> 0 | S14: ='13'!$V26 -> 0 | T14: ='14'!$V26 -> 0 | U14: ='15'!$V26 -> 0 | V14: ='16'!$V26 -> 0 | W14: ='17'!$V26 -> 0 | X14: ='18'!$V26 -> 0 | Y14: ='19'!$V26 -> 0 | Z14: ='20'!$V26 -> 0 | AA14: ='21'!$V26 -> 0 | AB14: =#REF! -> #REF! | AC14: =#REF! -> #REF! | AD14: =#REF! -> #REF! | AE14: =#REF! -> #REF! | AF14: =#REF! -> #REF! | AG14: =#REF! -> #REF! | AH14: =#REF! -> #REF! | AI14: =#REF! -> #REF! | ... AK14: =#REF! -> #REF!
D15: УСЛОВНЫЕ | E15: мин | F15: =SUM(G15:AK15) -> #REF! | G15: =SUM('1'!$I$21:$I$32) -> 0 | H15: =SUM('2'!$I$21:$I$32) -> 0 | I15: =SUM('3'!$I$21:$I$32) -> 0 | J15: =SUM('4'!$I$21:$I$32) -> 0 | K15: =SUM('5'!$I$21:$I$32) -> 0 | L15: =SUM('6'!$I$21:$I$32) -> 0 | M15: =SUM('7'!$I$21:$I$32) -> 0 | N15: =SUM('8'!$I$21:$I$32) -> -1.1538462 | O15: =SUM('9'!$I$21:$I$32) -> -24.461538 | P15: =SUM('10'!$I$21:$I$32) -> 0 | Q15: =SUM('11'!$I$21:$I$32) -> 0 | R15: =SUM('12'!$I$21:$I$32) -> 0 | S15: =SUM('13'!$I$21:$I$32) -> 5.7333333 | T15: =SUM('14'!$I$21:$I$32) -> 47.333333 | U15: =SUM('15'!$I$21:$I$32) -> 0 | V15: =SUM('16'!$I$21:$I$32) -> 0 | W15: =SUM('17'!$I$21:$I$32) -> 0 | X15: =SUM('18'!$I$21:$I$32) -> 0 | Y15: =SUM('19'!$I$21:$I$32) -> 0 | Z15: =SUM('20'!$I$21:$I$32) -> 0 | AA15: =SUM('21'!$I$21:$I$32) -> 0 | AB15: =SUM(#REF!) -> #REF! | AC15: =SUM(#REF!) -> #REF! | AD15: =SUM(#REF!) -> #REF! | AE15: =SUM(#REF!) -> #REF! | AF15: =SUM(#REF!) -> #REF! | AG15: =SUM(#REF!) -> #REF! | AH15: =SUM(#REF!) -> #REF! | AI15: =SUM(#REF!) -> #REF! | ... AK15: =SUM(#REF!) -> #REF!
D16: ИТОГО | E16: мин | F16: =SUM(F7:F15) -> #REF! | G16: =SUM(G7:G15) -> 0 | H16: =SUM(H7:H15) -> 0 | I16: =SUM(I7:I15) -> 0 | J16: =SUM(J7:J15) -> 0 | K16: =SUM(K7:K15) -> 0 | L16: =SUM(L7:L15) -> 0 | M16: =SUM(M7:M15) -> 0 | ... AK16: =SUM(AK7:AK15) -> #REF!
B18: Смена | C18: Показатель | E18: Ед. изм. | F18: ИТОГО | G18: 1 | H18: 2 | I18: 3 | J18: 4 | K18: 5 | L18: 6 | M18: 7 | N18: 8 | O18: 9 | P18: 10 | Q18: 11 | R18: 12 | S18: 13 | T18: 14 | U18: 15 | V18: 16 | W18: 17 | X18: 18 | Y18: 19 | Z18: 20 | AA18: 21 | AB18: 22 | AC18: 23 | AD18: 24 | AE18: 25 | AF18: 26 | AG18: 27 | AH18: 28 | AI18: 29 | AJ18: 30 | AK18: 31
B19: НОЧЬ | C19: Факт выпуска | E19: шт | F19: =SUM(G19:AK19) -> #REF! | G19: =SUM('1'!$K$136:$K$147) -> 0 | H19: =SUM('2'!$K$136:$K$147) -> 0 | I19: =SUM('3'!$K$136:$K$147) -> 0 | J19: =SUM('4'!$K$136:$K$147) -> 0 | K19: =SUM('5'!$K$136:$K$147) -> 0 | L19: =SUM('6'!$K$136:$K$147) -> 0 | M19: =SUM('7'!$K$136:$K$147) -> 0 | N19: =SUM('8'!$K$136:$K$147) -> 2390 | O19: =SUM('9'!$K$136:$K$147) -> 0 | P19: =SUM('10'!$K$136:$K$147) -> 0 | Q19: =SUM('11'!$K$136:$K$147) -> 0 | R19: =SUM('12'!$K$136:$K$147) -> 0 | S19: =SUM('13'!$K$136:$K$147) -> 1842 | T19: =SUM('14'!$K$136:$K$147) -> 0 | U19: =SUM('15'!$K$136:$K$147) -> 0 | V19: =SUM('16'!$K$136:$K$147) -> 0 | W19: =SUM('17'!$K$136:$K$147) -> 0 | X19: =SUM('18'!$K$136:$K$147) -> 0 | Y19: =SUM('19'!$K$136:$K$147) -> 0 | Z19: =SUM('20'!$K$136:$K$147) -> 2425 | AA19: =SUM('21'!$K$136:$K$147) -> 0 | AB19: =SUM(#REF!) -> #REF! | AC19: =SUM(#REF!) -> #REF! | AD19: =SUM(#REF!) -> #REF! | AE19: =SUM(#REF!) -> #REF! | AF19: =SUM(#REF!) -> #REF! | AG19: =SUM(#REF!) -> #REF! | AH19: =SUM(#REF!) -> #REF! | AI19: =SUM(#REF!) -> #REF! | ... AK19: =SUM(#REF!) -> #REF!
C20: Продуктивное время | E20: мин | F20: =SUM(G20:AK20) -> #REF! | G20: =SUM('1'!$F$136:$F$147) -> 0 | H20: =SUM('2'!$F$136:$F$147) -> 0 | I20: =SUM('3'!$F$136:$F$147) -> 0 | J20: =SUM('4'!$F$136:$F$147) -> 0 | K20: =SUM('5'!$F$136:$F$147) -> 0 | L20: =SUM('6'!$F$136:$F$147) -> 0 | M20: =SUM('7'!$F$136:$F$147) -> 0 | N20: =SUM('8'!$F$136:$F$147) -> 220.61538 | O20: =SUM('9'!$F$136:$F$147) -> 0 | P20: =SUM('10'!$F$136:$F$147) -> 0 | Q20: =SUM('11'!$F$136:$F$147) -> 0 | R20: =SUM('12'!$F$136:$F$147) -> 0 | S20: =SUM('13'!$F$136:$F$147) -> 245.6 | T20: =SUM('14'!$F$136:$F$147) -> 0 | U20: =SUM('15'!$F$136:$F$147) -> 0 | V20: =SUM('16'!$F$136:$F$147) -> 0 | W20: =SUM('17'!$F$136:$F$147) -> 0 | X20: =SUM('18'!$F$136:$F$147) -> 0 | Y20: =SUM('19'!$F$136:$F$147) -> 0 | Z20: =SUM('20'!$F$136:$F$147) -> 246.61017 | AA20: =SUM('21'!$F$136:$F$147) -> 0 | AB20: =SUM(#REF!) -> #REF! | AC20: =SUM(#REF!) -> #REF! | AD20: =SUM(#REF!) -> #REF! | AE20: =SUM(#REF!) -> #REF! | AF20: =SUM(#REF!) -> #REF! | AG20: =SUM(#REF!) -> #REF! | AH20: =SUM(#REF!) -> #REF! | AI20: =SUM(#REF!) -> #REF! | ... AK20: =SUM(#REF!) -> #REF!
C21: Факт время | E21: мин | F21: =SUM(G21:AK21) -> #REF! | G21: =SUM('1'!$D$136:$D$147) -> 0 | H21: =SUM('2'!$D$136:$D$147) -> 0 | I21: =SUM('3'!$D$136:$D$147) -> 0 | J21: =SUM('4'!$D$136:$D$147) -> 0 | K21: =SUM('5'!$D$136:$D$147) -> 0 | L21: =SUM('6'!$D$136:$D$147) -> 0 | M21: =SUM('7'!$D$136:$D$147) -> 0 | N21: =SUM('8'!$D$136:$D$147) -> 720 | O21: =SUM('9'!$D$136:$D$147) -> 0 | P21: =SUM('10'!$D$136:$D$147) -> 0 | Q21: =SUM('11'!$D$136:$D$147) -> 0 | R21: =SUM('12'!$D$136:$D$147) -> 0 | S21: =SUM('13'!$D$136:$D$147) -> 720 | T21: =SUM('14'!$D$136:$D$147) -> 0 | U21: =SUM('15'!$D$136:$D$147) -> 0 | V21: =SUM('16'!$D$136:$D$147) -> 0 | W21: =SUM('17'!$D$136:$D$147) -> 0 | X21: =SUM('18'!$D$136:$D$147) -> 0 | Y21: =SUM('19'!$D$136:$D$147) -> 0 | Z21: =SUM('20'!$D$136:$D$147) -> 530 | AA21: =SUM('21'!$D$136:$D$147) -> 0 | AB21: =SUM(#REF!) -> #REF! | AC21: =SUM(#REF!) -> #REF! | AD21: =SUM(#REF!) -> #REF! | AE21: =SUM(#REF!) -> #REF! | AF21: =SUM(#REF!) -> #REF! | AG21: =SUM(#REF!) -> #REF! | AH21: =SUM(#REF!) -> #REF! | AI21: =SUM(#REF!) -> #REF! | ... AK21: =SUM(#REF!) -> #REF!
C23: ПРОСТОИ | D23: ПЛАНОВЫЕ | E23: мин | F23: =SUM(G23:AK23) -> #REF! | G23: ='1'!$V134 -> 0 | H23: ='2'!$V134 -> 0 | I23: ='3'!$V134 -> 0 | J23: ='4'!$V134 -> 0 | K23: ='5'!$V134 -> 0 | L23: ='6'!$V134 -> 0 | M23: ='7'!$V134 -> 0 | N23: ='8'!$V134 -> 0 | O23: ='9'!$V134 -> 0 | P23: ='10'!$V134 -> 0 | Q23: ='11'!$V134 -> 0 | R23: ='12'!$V134 -> 0 | S23: ='13'!$V134 -> 0 | T23: ='14'!$V134 -> 0 | U23: ='15'!$V134 -> 0 | V23: ='16'!$V134 -> 0 | W23: ='17'!$V134 -> 0 | X23: ='18'!$V134 -> 0 | Y23: ='19'!$V134 -> 0 | Z23: ='20'!$V134 -> 20 | AA23: ='21'!$V134 -> 0 | AB23: =#REF! -> #REF! | AC23: =#REF! -> #REF! | AD23: =#REF! -> #REF! | AE23: =#REF! -> #REF! | AF23: =#REF! -> #REF! | AG23: =#REF! -> #REF! | AH23: =#REF! -> #REF! | AI23: =#REF! -> #REF! | ... AK23: =#REF! -> #REF!
D24: ПРОИЗВОДСТВЕННЫЕ | E24: мин | F24: =SUM(G24:AK24) -> #REF! | G24: ='1'!$V135 -> 0 | H24: ='2'!$V135 -> 0 | I24: ='3'!$V135 -> 0 | J24: ='4'!$V135 -> 0 | K24: ='5'!$V135 -> 0 | L24: ='6'!$V135 -> 0 | M24: ='7'!$V135 -> 0 | N24: ='8'!$V135 -> 0 | O24: ='9'!$V135 -> 0 | P24: ='10'!$V135 -> 0 | Q24: ='11'!$V135 -> 0 | R24: ='12'!$V135 -> 0 | S24: ='13'!$V135 -> 0 | T24: ='14'!$V135 -> 0 | U24: ='15'!$V135 -> 0 | V24: ='16'!$V135 -> 0 | W24: ='17'!$V135 -> 0 | X24: ='18'!$V135 -> 0 | Y24: ='19'!$V135 -> 0 | Z24: ='20'!$V135 -> 0 | AA24: ='21'!$V135 -> 0 | AB24: =#REF! -> #REF! | AC24: =#REF! -> #REF! | AD24: =#REF! -> #REF! | AE24: =#REF! -> #REF! | AF24: =#REF! -> #REF! | AG24: =#REF! -> #REF! | AH24: =#REF! -> #REF! | AI24: =#REF! -> #REF! | ... AK24: =#REF! -> #REF!
D25: ТЕХНИЧЕСКИЕ | E25: мин | F25: =SUM(G25:AK25) -> #REF! | G25: ='1'!$V136 -> 0 | H25: ='2'!$V136 -> 0 | I25: ='3'!$V136 -> 0 | J25: ='4'!$V136 -> 0 | K25: ='5'!$V136 -> 0 | L25: ='6'!$V136 -> 0 | M25: ='7'!$V136 -> 0 | N25: ='8'!$V136 -> 500 | O25: ='9'!$V136 -> 0 | P25: ='10'!$V136 -> 0 | Q25: ='11'!$V136 -> 0 | R25: ='12'!$V136 -> 0 | S25: ='13'!$V136 -> 240 | T25: ='14'!$V136 -> 0 | U25: ='15'!$V136 -> 0 | V25: ='16'!$V136 -> 0 | W25: ='17'!$V136 -> 0 | X25: ='18'!$V136 -> 0 | Y25: ='19'!$V136 -> 0 | Z25: ='20'!$V136 -> 253 | AA25: ='21'!$V136 -> 0 | AB25: =#REF! -> #REF! | AC25: =#REF! -> #REF! | AD25: =#REF! -> #REF! | AE25: =#REF! -> #REF! | AF25: =#REF! -> #REF! | AG25: =#REF! -> #REF! | AH25: =#REF! -> #REF! | AI25: =#REF! -> #REF! | ... AK25: =#REF! -> #REF!
D26: ТЕХНОЛОГИЧЕСКИЕ | E26: мин | F26: =SUM(G26:AK26) -> #REF! | G26: ='1'!$V137 -> 0 | H26: ='2'!$V137 -> 0 | I26: ='3'!$V137 -> 0 | J26: ='4'!$V137 -> 0 | K26: ='5'!$V137 -> 0 | L26: ='6'!$V137 -> 0 | M26: ='7'!$V137 -> 0 | N26: ='8'!$V137 -> 0 | O26: ='9'!$V137 -> 0 | P26: ='10'!$V137 -> 0 | Q26: ='11'!$V137 -> 0 | R26: ='12'!$V137 -> 0 | S26: ='13'!$V137 -> 0 | T26: ='14'!$V137 -> 0 | U26: ='15'!$V137 -> 0 | V26: ='16'!$V137 -> 0 | W26: ='17'!$V137 -> 0 | X26: ='18'!$V137 -> 0 | Y26: ='19'!$V137 -> 0 | Z26: ='20'!$V137 -> 0 | AA26: ='21'!$V137 -> 0 | AB26: =#REF! -> #REF! | AC26: =#REF! -> #REF! | AD26: =#REF! -> #REF! | AE26: =#REF! -> #REF! | AF26: =#REF! -> #REF! | AG26: =#REF! -> #REF! | AH26: =#REF! -> #REF! | AI26: =#REF! -> #REF! | ... AK26: =#REF! -> #REF!
D27: ЛАБОРАТОРНЫЕ | E27: мин | F27: =SUM(G27:AK27) -> #REF! | G27: ='1'!$V138 -> 0 | H27: ='2'!$V138 -> 0 | I27: ='3'!$V138 -> 0 | J27: ='4'!$V138 -> 0 | K27: ='5'!$V138 -> 0 | L27: ='6'!$V138 -> 0 | M27: ='7'!$V138 -> 0 | N27: ='8'!$V138 -> 0 | O27: ='9'!$V138 -> 0 | P27: ='10'!$V138 -> 0 | Q27: ='11'!$V138 -> 0 | R27: ='12'!$V138 -> 0 | S27: ='13'!$V138 -> 0 | T27: ='14'!$V138 -> 0 | U27: ='15'!$V138 -> 0 | V27: ='16'!$V138 -> 0 | W27: ='17'!$V138 -> 0 | X27: ='18'!$V138 -> 0 | Y27: ='19'!$V138 -> 0 | Z27: ='20'!$V138 -> 10 | AA27: ='21'!$V138 -> 0 | AB27: =#REF! -> #REF! | AC27: =#REF! -> #REF! | AD27: =#REF! -> #REF! | AE27: =#REF! -> #REF! | AF27: =#REF! -> #REF! | AG27: =#REF! -> #REF! | AH27: =#REF! -> #REF! | AI27: =#REF! -> #REF! | ... AK27: =#REF! -> #REF!
D28: СЫРЬЕВЫЕ | E28: мин | F28: =SUM(G28:AK28) -> #REF! | G28: ='1'!$V139 -> 0 | H28: ='2'!$V139 -> 0 | I28: ='3'!$V139 -> 0 | J28: ='4'!$V139 -> 0 | K28: ='5'!$V139 -> 0 | L28: ='6'!$V139 -> 0 | M28: ='7'!$V139 -> 0 | N28: ='8'!$V139 -> 0 | O28: ='9'!$V139 -> 0 | P28: ='10'!$V139 -> 0 | Q28: ='11'!$V139 -> 0 | R28: ='12'!$V139 -> 0 | S28: ='13'!$V139 -> 0 | T28: ='14'!$V139 -> 0 | U28: ='15'!$V139 -> 0 | V28: ='16'!$V139 -> 0 | W28: ='17'!$V139 -> 0 | X28: ='18'!$V139 -> 0 | Y28: ='19'!$V139 -> 0 | Z28: ='20'!$V139 -> 0 | AA28: ='21'!$V139 -> 0 | AB28: =#REF! -> #REF! | AC28: =#REF! -> #REF! | AD28: =#REF! -> #REF! | AE28: =#REF! -> #REF! | AF28: =#REF! -> #REF! | AG28: =#REF! -> #REF! | AH28: =#REF! -> #REF! | AI28: =#REF! -> #REF! | ... AK28: =#REF! -> #REF!
D29: ЛОГИСТИЧЕСКИЕ | E29: мин | F29: =SUM(G29:AK29) -> #REF! | G29: ='1'!$V140 -> 0 | H29: ='2'!$V140 -> 0 | I29: ='3'!$V140 -> 0 | J29: ='4'!$V140 -> 0 | K29: ='5'!$V140 -> 0 | L29: ='6'!$V140 -> 0 | M29: ='7'!$V140 -> 0 | N29: ='8'!$V140 -> 0 | O29: ='9'!$V140 -> 0 | P29: ='10'!$V140 -> 0 | Q29: ='11'!$V140 -> 0 | R29: ='12'!$V140 -> 0 | S29: ='13'!$V140 -> 0 | T29: ='14'!$V140 -> 0 | U29: ='15'!$V140 -> 0 | V29: ='16'!$V140 -> 0 | W29: ='17'!$V140 -> 0 | X29: ='18'!$V140 -> 0 | Y29: ='19'!$V140 -> 0 | Z29: ='20'!$V140 -> 0 | AA29: ='21'!$V140 -> 0 | AB29: =#REF! -> #REF! | AC29: =#REF! -> #REF! | AD29: =#REF! -> #REF! | AE29: =#REF! -> #REF! | AF29: =#REF! -> #REF! | AG29: =#REF! -> #REF! | AH29: =#REF! -> #REF! | AI29: =#REF! -> #REF! | ... AK29: =#REF! -> #REF!
D30: ОБЩЕЗАВОДСКИЕ | E30: мин | F30: =SUM(G30:AK30) -> #REF! | G30: ='1'!$V141 -> 0 | H30: ='2'!$V141 -> 0 | I30: ='3'!$V141 -> 0 | J30: ='4'!$V141 -> 0 | K30: ='5'!$V141 -> 0 | L30: ='6'!$V141 -> 0 | M30: ='7'!$V141 -> 0 | N30: ='8'!$V141 -> 0 | O30: ='9'!$V141 -> 0 | P30: ='10'!$V141 -> 0 | Q30: ='11'!$V141 -> 0 | R30: ='12'!$V141 -> 0 | S30: ='13'!$V141 -> 0 | T30: ='14'!$V141 -> 0 | U30: ='15'!$V141 -> 0 | V30: ='16'!$V141 -> 0 | W30: ='17'!$V141 -> 0 | X30: ='18'!$V141 -> 0 | Y30: ='19'!$V141 -> 0 | Z30: ='20'!$V141 -> 0 | AA30: ='21'!$V141 -> 0 | AB30: =#REF! -> #REF! | AC30: =#REF! -> #REF! | AD30: =#REF! -> #REF! | AE30: =#REF! -> #REF! | AF30: =#REF! -> #REF! | AG30: =#REF! -> #REF! | AH30: =#REF! -> #REF! | AI30: =#REF! -> #REF! | ... AK30: =#REF! -> #REF!
D31: УСЛОВНЫЕ | E31: мин | F31: =SUM(G31:AK31) -> -0.61538462 | G31: =SUM('1'!$I$136:$I$147) -> 0 | H31: =SUM('2'!$I$136:$I$147) -> 0 | I31: =SUM('3'!$I$136:$I$147) -> 0 | J31: =SUM('4'!$I$136:$I$147) -> 0 | K31: =SUM('5'!$I$136:$I$147) -> 0 | L31: =SUM('6'!$I$136:$I$147) -> 0 | M31: =SUM('7'!$I$136:$I$147) -> 0 | N31: =SUM('8'!$I$136:$I$147) -> -0.61538462 | O31: =SUM('9'!$I$136:$I$147) -> 0 | P31: =SUM('10'!$I$136:$I$147) -> 0 | Q31: =SUM('1'!$I$136:$I$147) -> 0 | R31: =SUM('1'!$I$136:$I$147) -> 0 | S31: =SUM('1'!$I$136:$I$147) -> 0 | T31: =SUM('1'!$I$136:$I$147) -> 0 | U31: =SUM('1'!$I$136:$I$147) -> 0 | V31: =SUM('1'!$I$136:$I$147) -> 0 | W31: =SUM('1'!$I$136:$I$147) -> 0 | X31: =SUM('1'!$I$136:$I$147) -> 0 | ... AK31: =SUM('1'!$I$136:$I$147) -> 0
D32: ИТОГО | E32: мин | F32: =SUM(F23:F31) -> #REF! | G32: =SUM(G23:G31) -> 0 | H32: =SUM(H23:H31) -> 0 | I32: =SUM(I23:I31) -> 0 | J32: =SUM(J23:J31) -> 0 | K32: =SUM(K23:K31) -> 0 | L32: =SUM(L23:L31) -> 0 | M32: =SUM(M23:M31) -> 0 | ... AK32: =SUM(AK23:AK31) -> #REF!
B34: Смена | C34: Показатель | E34: Ед. изм. | F34: ИТОГО | G34: 1 | H34: 2 | I34: 3 | J34: 4 | K34: 5 | L34: 6 | M34: 7 | N34: 8 | O34: 9 | P34: 10 | Q34: 11 | R34: 12 | S34: 13 | T34: 14 | U34: 15 | V34: 16 | W34: 17 | X34: 18 | Y34: 19 | Z34: 20 | AA34: 21 | AB34: 22 | AC34: 23 | AD34: 24 | AE34: 25 | AF34: 26 | AG34: 27 | AH34: 28 | AI34: 29 | AJ34: 30 | AK34: 31
B35: СУТКИ | C35: Факт выпуска | E35: шт | F35: =SUM(G35:AK35) -> #REF! | G35: =G3+G19 -> 0 | H35: =H3+H19 -> 0 | I35: =I3+I19 -> 0 | J35: =J3+J19 -> 0 | K35: =K3+K19 -> 0 | L35: =L3+L19 -> 0 | M35: =M3+M19 -> 0 | N35: =N3+N19 -> 4125 | ... AK35: =AK3+AK19 -> #REF!
C36: Продуктивное время | E36: мин | F36: =SUM(G36:AK36) -> #REF! | G36: =G4+G20 -> 0 | H36: =H4+H20 -> 0 | I36: =I4+I20 -> 0 | J36: =J4+J20 -> 0 | K36: =K4+K20 -> 0 | L36: =L4+L20 -> 0 | M36: =M4+M20 -> 0 | N36: =N4+N20 -> 380.76923 | ... AK36: =AK4+AK20 -> #REF!
C37: Факт время | E37: мин | F37: =SUM(G37:AK37) -> #REF! | G37: =G5+G21 -> 0 | H37: =H5+H21 -> 0 | I37: =I5+I21 -> 0 | J37: =J5+J21 -> 0 | K37: =K5+K21 -> 0 | L37: =L5+L21 -> 0 | M37: =M5+M21 -> 0 | N37: =N5+N21 -> 1320 | ... AK37: =AK5+AK21 -> #REF!
C39: ПРОСТОИ | D39: ПЛАНОВЫЕ | E39: мин | F39: =SUM(G39:AK39) -> #REF! | G39: =G7+G23 -> 0 | H39: =H7+H23 -> 0 | I39: =I7+I23 -> 0 | J39: =J7+J23 -> 0 | K39: =K7+K23 -> 0 | L39: =L7+L23 -> 0 | M39: =M7+M23 -> 0 | N39: =N7+N23 -> 0 | ... AK39: =AK7+AK23 -> #REF!
D40: ПРОИЗВОДСТВЕННЫЕ | E40: мин | F40: =SUM(G40:AK40) -> #REF! | G40: =G8+G24 -> 0 | H40: =H8+H24 -> 0 | I40: =I8+I24 -> 0 | J40: =J8+J24 -> 0 | K40: =K8+K24 -> 0 | L40: =L8+L24 -> 0 | M40: =M8+M24 -> 0 | N40: =N8+N24 -> 0 | ... AK40: =AK8+AK24 -> #REF!
D41: ТЕХНИЧЕСКИЕ | E41: мин | F41: =SUM(G41:AK41) -> #REF! | G41: =G9+G25 -> 0 | H41: =H9+H25 -> 0 | I41: =I9+I25 -> 0 | J41: =J9+J25 -> 0 | K41: =K9+K25 -> 0 | L41: =L9+L25 -> 0 | M41: =M9+M25 -> 0 | N41: =N9+N25 -> 941 | ... AK41: =AK9+AK25 -> #REF!
D42: ТЕХНОЛОГИЧЕСКИЕ | E42: мин | F42: =SUM(G42:AK42) -> #REF! | G42: =G10+G26 -> 0 | H42: =H10+H26 -> 0 | I42: =I10+I26 -> 0 | J42: =J10+J26 -> 0 | K42: =K10+K26 -> 0 | L42: =L10+L26 -> 0 | M42: =M10+M26 -> 0 | N42: =N10+N26 -> 0 | ... AK42: =AK10+AK26 -> #REF!
D43: ЛАБОРАТОРНЫЕ | E43: мин | F43: =SUM(G43:AK43) -> #REF! | G43: =G11+G27 -> 0 | H43: =H11+H27 -> 0 | I43: =I11+I27 -> 0 | J43: =J11+J27 -> 0 | K43: =K11+K27 -> 0 | L43: =L11+L27 -> 0 | M43: =M11+M27 -> 0 | N43: =N11+N27 -> 0 | ... AK43: =AK11+AK27 -> #REF!
D44: СЫРЬЕВЫЕ | E44: мин | F44: =SUM(G44:AK44) -> #REF! | G44: =G12+G28 -> 0 | H44: =H12+H28 -> 0 | I44: =I12+I28 -> 0 | J44: =J12+J28 -> 0 | K44: =K12+K28 -> 0 | L44: =L12+L28 -> 0 | M44: =M12+M28 -> 0 | N44: =N12+N28 -> 0 | ... AK44: =AK12+AK28 -> #REF!
D45: ЛОГИСТИЧЕСКИЕ | E45: мин | F45: =SUM(G45:AK45) -> #REF! | G45: =G13+G29 -> 0 | H45: =H13+H29 -> 0 | I45: =I13+I29 -> 0 | J45: =J13+J29 -> 0 | K45: =K13+K29 -> 0 | L45: =L13+L29 -> 0 | M45: =M13+M29 -> 0 | N45: =N13+N29 -> 0 | ... AK45: =AK13+AK29 -> #REF!
...

Sheet 1
A1: Сменный отчет выпуска продукции
A2: Линия розлива № 6 - 3,0 л.
A3: Смена "Д" день с 08:00 по 20:00 | F3: Сутки план/факт | G3: =SUM(J21:J32)+SUM(J136:J147) -> 0 | H3: =SUM(K21:K32)+SUM(K136:K147) -> 0 | I3: паспортная скорость | J3: 650 | K3: Время смены | L3: 720
A4: Должность | F4: ФИО ответственного | I4: Рабочее место оператора | K4: ФИО оператора | N4: Поля для заполнения
A5: Начальник смены | I5: Розлив | O5: ФИКСИРОВАННЫЕ ПОЛЯ, НЕ ЗАПОЛНЯТЬ
A6: Мастер | I6: Упаковка
A7: Контролер | I7: Упаковка | O7: ПОЛЯ ДЛЯ ЗАПОЛНЕНИЯ МАСТЕРОМ
A8: Наладчик оборудования | I8: Упаковка
A9: Наладчик оборудования | I9: Упаковка
A14: ИТОГОВЫЙ РЕЗУЛЬТАТ РАБОТЫ СМЕНЫ (ВЫЧИСЛЯЕТСЯ АВТОМАТИЧЕСКИ) | N14: ПРОСТОИ (ВЫЧИСЛЯЕТСЯ АВТОМАТИЧЕСКИ)
A15: НАИМЕНОВАНИЕ НАПИТКА | B15: Время начала производства | C15: Время окончания производства | D15: Время работы смены | E15: Плановая производительность | F15: Приведенное продуктивное время | G15: Эффективность от паспортной скорости % | H15: Вычитаемые простои (плановые, общезаводские) | I15: Условные простои (Необоснованные потери), мин | J15: Расчетная плановая производительность с учетом вычитаемых простоев | K15: Фактическая производительность за смену | L15: Выполнение сменного задания %, невыполнение -, перевыполнение + | N15: Вид Простоя | P15: Длительность, час | V15: Итого
N19: ПЛАНОВЫЕ | P19: =SUM(S47:S58) -> 0 | Q19: =SUM(S59:S69) -> 0 | R19: =SUM(S70:S80) -> 0 | S19: =SUM(S81:S91) -> 0 | T19: =SUM(S92:S102) -> 0 | U19: =SUM(S103:S113) -> 0 | V19: =P19+Q19+R19+S19+T19+U19 -> 0
D20: [мин] | E20: [шт./час] | F20: [мин] | H20: [мин] | J20: [шт./смену] | K20: [шт./смену] | L20: % | N20: ПРОИЗВОДСТВЕННЫЕ | P20: =SUM(T46:T57) -> 0 | Q20: =SUM(T58:T68) -> 0 | R20: =SUM(T69:T79) -> 0 | S20: =SUM(T80:T90) -> 0 | T20: =SUM(T91:T101) -> 0 | U20: =SUM(T102:T112) -> 0 | V20: =P20+Q20+R20+S20+T20+U20 -> 0
A21: =A37 -> 0 | D21: =(C21-B21+(C21<B21))*24*60 -> 0 | F21: =IF(E21=0,0,(F37/J3*60)) -> 0 | G21: =IF($K21=0,0,(K21*100)/(D21*$J$3/60)) -> 0 | H21: =P19+P26 -> 0 | I21: =D21-F21-P27 -> 0 | J21: =(D21-H21)/60*E21 -> 0 | K21: =F37 -> 0 | L21: =IF($K21=0,0,K21/J21) -> 0 | N21: ТЕХНИЧЕСКИЕ | P21: =SUM(U46:U57) -> 0 | Q21: =SUM(U58:U68) -> 0 | R21: =SUM(U69:U79) -> 0 | S21: =SUM(U80:U90) -> 0 | T21: =SUM(U91:U101) -> 0 | U21: =SUM(U102:U112) -> 0 | V21: =P21+Q21+R21+S21+T21+U21 -> 0
L22: =K21-J21 -> 0 | N22: ТЕХНОЛОГИЧЕСКИЕ | P22: =SUM(V46:V57) -> 0 | Q22: =SUM(V58:V68) -> 0 | R22: =SUM(V69:V79) -> 0 | S22: =SUM(V80:V90) -> 0 | T22: =SUM(V91:V101) -> 0 | U22: =SUM(V102:V112) -> 0 | V22: =P22+Q22+R22+S22+T22+U22 -> 0
A23: =A38 -> 0 | D23: =(C23-B23+(C23<B23))*24*60 -> 0 | F23: =IF(E23=0,0,(F38/J3*60)) -> 0 | G23: =IF($K23=0,0,(K23*100)/(D23*$J$3/60)) -> 0 | H23: =Q19+Q26 -> 0 | I23: =D23-F23-Q27 -> 0 | J23: =(D23-H23)/60*E23 -> 0 | K23: =F38 -> 0 | L23: =IF($K23=0,0,K23/J23) -> 0 | N23: ЛАБОРАТОРНЫЕ | P23: =SUM(W46:W57) -> 0 | Q23: =SUM(W58:W68) -> 0 | R23: =SUM(W69:W79) -> 0 | S23: =SUM(W80:W90) -> 0 | T23: =SUM(W91:W101) -> 0 | U23: =SUM(W102:W112) -> 0 | V23: =P23+Q23+R23+S23+T23+U23 -> 0
L24: =K23-J23 -> 0 | N24: СЫРЬЕВЫЕ | P24: =SUM(X46:X57) -> 0 | Q24: =SUM(X58:X68) -> 0 | R24: =SUM(X69:X79) -> 0 | S24: =SUM(X80:X90) -> 0 | T24: =SUM(X91:X101) -> 0 | U24: =SUM(X102:X112) -> 0 | V24: =P24+Q24+R24+S24+T24+U24 -> 0
A25: =A39 -> 0 | D25: =(C25-B25+(C25<B25))*24*60 -> 0 | F25: =IF(E25=0,0,(F39/J3*60)) -> 0 | G25: =IF($K25=0,0,(K25*100)/(D25*$J$3/60)) -> 0 | H25: =R19+R26 -> 0 | I25: =D25-F25-R27 -> 0 | J25: =(D25-H25)/60*E25 -> 0 | K25: =F39 -> 0 | L25: =IF($K25=0,0,K25/J25) -> 0 | N25: ЛОГИСТИЧЕСКИЕ | P25: =SUM(Y46:Y57) -> 0 | Q25: =SUM(Y58:Y68) -> 0 | R25: =SUM(Y69:Y79) -> 0 | S25: =SUM(Y80:Y90) -> 0 | T25: =SUM(Y91:Y101) -> 0 | U25: =SUM(Y102:Y112) -> 0 | V25: =P25+Q25+R25+S25+T25+U25 -> 0
L26: =K25-J25 -> 0 | N26: ОБЩЕЗАВОДСКИЕ | P26: =SUM(Z46:Z57) -> 0 | Q26: =SUM(Z58:Z68) -> 0 | R26: =SUM(Z69:Z79) -> 0 | S26: =SUM(Z80:Z90) -> 0 | T26: =SUM(Z91:Z101) -> 0 | U26: =SUM(Z102:Z112) -> 0 | V26: =P26+Q26+R26+S26+T26+U26 -> 0
A27: =A40 -> 0 | D27: =(C27-B27+(C27<B27))*24*60 -> 0 | F27: =IF(E27=0,0,(F40/J3*60)) -> 0 | G27: =IF($K27=0,0,(K27*100)/(D27*$J$3/60)) -> 0 | H27: =S19+S26 -> 0 | I27: =D27-F27-S27 -> 0 | J27: =(D27-H27)/60*E27 -> 0 | K27: =F40 -> 0 | L27: =IF($K27=0,0,K27/J27) -> 0 | N27: ИТОГО | P27: =SUM(P18:P26) -> 0 | Q27: =SUM(Q18:Q26) -> 0 | R27: =SUM(R18:R26) -> 0 | S27: =SUM(S18:S26) -> 0 | T27: =SUM(T18:T26) -> 0 | U27: =SUM(U18:U26) -> 0 | V27: =P27+Q27+R27+S27+T27+U27 -> 0
L28: =K27-J27 -> 0
A29: =A41 -> 0 | D29: =(C29-B29+(C29<B29))*24*60 -> 0 | F29: =IF(E29=0,0,(F41/J3*60)) -> 0 | G29: =IF($K29=0,0,(K29*100)/(D29*$J$3/60)) -> 0 | H29: =T19+T26 -> 0 | I29: =D29-F29-T27 -> 0 | J29: =(D29-H29)/60*E29 -> 0 | K29: =F41 -> 0 | L29: =IF($K29=0,0,K29/J29) -> 0
L30: =K29-J29 -> 0
A31: =A42 -> 0 | D31: =(C31-B31+(C31<B31))*24*60 -> 0 | F31: =IF(E31=0,0,(F42/J3*60)) -> 0 | G31: =IF($K31=0,0,(K31*100)/(D31*$J$3/60)) -> 0 | H31: =U19+U26 -> 0 | I31: =D31-F31-U27 -> 0 | J31: =(D31-H31)/60*E31 -> 0 | K31: =F42 -> 0 | L31: =IF($K31=0,0,K31/J31) -> 0
L32: =K31-J31 -> 0
A33: НАИМЕНОВАНИЕ И КОЛИЧЕСТВО ПРОИЗВЕДЕННОЙ ПРОДУКЦИИ (ЗАПОЛНЯЕТСЯ МАСТЕРОМ) | J33: Итого план | K33: Итого факт | L33: =IF($K34=0,0,K34/J34) -> 0
J34: =J21+J23+J25+J27+J29+J31 -> 0 | K34: =K21+K23+K25+K27+K29+K31 -> 0
A35: Наименование продукции, формат | F35: Выпуск по счетчику | G35: Сдано на склад гп | L35: Средний коэффициент по смене
K37: =G37 -> 0
K38: =G38 -> 0
K39: =G39 -> 0
K40: =G40 -> 0
K41: =G41 -> 0
K42: =G42 -> 0
A43: ИТОГО ПРОИЗВЕДЕНО ПРОДУКЦИИ | K43: =SUM(K37:K42) -> 0 | L43: =SUM(L38+L38) -> 0
A45: Наименование продукции, формат | B45: Время, час | D45: Объем производства, шт | E45: Автомат | F45: Описание простоя, причины | H45: Вид простоя | I45: Период простоя | K45: Время (мин) | L45: Корректирующие мероприятия | O45: Ответственный | P45: Сроки | Q45: Статус выполнения | S45: ПРОСТОИ
I46: Начало | J46: Конец | S46: ПЛАНОВЫЕ | T46: ПРОИЗВОДСТВЕННЫЕ | U46: ТЕХНИЧЕСКИЕ | V46: ТЕХНОЛОГИЧЕСКИЕ | W46: ЛАБОРАТОРНЫЕ | X46: СЫРЬЕВЫЕ | Y46: ЛОГИСТИЧЕСКИЕ | Z46: ОБЩЕЗАВОДСКИЕ
A47: =A37 -> 0 | B47: =B21 -> 0 | C47: =B47+1/24 -> 0.041666667 | K47: =(J47-I47+(J47<I47))*24*60 -> 0 | O47: =IF(H47=$V$5,$F$7,"") -> 0 | S47: =IF($H47="ПЛАНОВЫЕ",$K47,0) -> 0 | T47: =IF($H47="ПРОИЗВОДСТВЕННЫЕ",$K47,0) -> 0 | U47: =IF($H47="ТЕХНИЧЕСКИЕ",$K47,0) -> 0 | V47: =IF($H47="ТЕХНОЛОГИЧЕСКИЕ",$K47,0) -> 0 | W47: =IF($H47="ЛАБОРАТОРНЫЕ",$K47,0) -> 0 | X47: =IF($H47="СЫРЬЕВЫЕ",$K47,0) -> 0 | Y47: =IF($H47="ЛОГИСТИЧЕСКИЕ",$K47,0) -> 0 | Z47: =IF($H47="ОБЩЕЗАВОДСКИЕ",$K47,0) -> 0
B48: =C47 -> 0.041666667 | C48: =B48+1/24 -> 0.083333333 | K48: =(J48-I48+(J48<I48))*24*60 -> 0 | O48: =IF(H48=$V$5,$F$7,"") -> 0 | S48: =IF($H48="ПЛАНОВЫЕ",$K48,0) -> 0 | T48: =IF($H48="ПРОИЗВОДСТВЕННЫЕ",$K48,0) -> 0 | U48: =IF($H48="ТЕХНИЧЕСКИЕ",$K48,0) -> 0 | V48: =IF($H48="ТЕХНОЛОГИЧЕСКИЕ",$K48,0) -> 0 | W48: =IF($H48="ЛАБОРАТОРНЫЕ",$K48,0) -> 0 | X48: =IF($H48="СЫРЬЕВЫЕ",$K48,0) -> 0 | Y48: =IF($H48="ЛОГИСТИЧЕСКИЕ",$K48,0) -> 0 | Z48: =IF($H48="ОБЩЕЗАВОДСКИЕ",$K48,0) -> 0
B49: =C48 -> 0.083333333 | C49: =B49+1/24 -> 0.125 | K49: =(J49-I49+(J49<I49))*24*60 -> 0 | O49: =IF(H49=$V$5,$F$7,"") -> 0 | S49: =IF($H49="ПЛАНОВЫЕ",$K49,0) -> 0 | T49: =IF($H49="ПРОИЗВОДСТВЕННЫЕ",$K49,0) -> 0 | U49: =IF($H49="ТЕХНИЧЕСКИЕ",$K49,0) -> 0 | V49: =IF($H49="ТЕХНОЛОГИЧЕСКИЕ",$K49,0) -> 0 | W49: =IF($H49="ЛАБОРАТОРНЫЕ",$K49,0) -> 0 | X49: =IF($H49="СЫРЬЕВЫЕ",$K49,0) -> 0 | Y49: =IF($H49="ЛОГИСТИЧЕСКИЕ",$K49,0) -> 0 | Z49: =IF($H49="ОБЩЕЗАВОДСКИЕ",$K49,0) -> 0
...

Sheet 2
A1: Сменный отчет выпуска продукции
A2: Линия розлива № 6 - 3,0 л.
A3: Смена "Д" день с 08:00 по 20:00 | F3: Сутки план/факт | G3: =SUM(J21:J32)+SUM(J136:J147) -> 0 | H3: =SUM(K21:K32)+SUM(K136:K147) -> 0 | I3: паспортная скорость | J3: 650 | K3: Время смены | L3: 720
A4: Должность | F4: ФИО ответственного | I4: Рабочее место оператора | K4: ФИО оператора | N4: Поля для заполнения
A5: Начальник смены | I5: Розлив | O5: ФИКСИРОВАННЫЕ ПОЛЯ, НЕ ЗАПОЛНЯТЬ
A6: Мастер | I6: Упаковка
A7: Контролер | I7: Упаковка | O7: ПОЛЯ ДЛЯ ЗАПОЛНЕНИЯ МАСТЕРОМ
A8: Наладчик оборудования | I8: Упаковка
A9: Наладчик оборудования | I9: Упаковка
A14: ИТОГОВЫЙ РЕЗУЛЬТАТ РАБОТЫ СМЕНЫ (ВЫЧИСЛЯЕТСЯ АВТОМАТИЧЕСКИ) | N14: ПРОСТОИ (ВЫЧИСЛЯЕТСЯ АВТОМАТИЧЕСКИ)
A15: НАИМЕНОВАНИЕ НАПИТКА | B15: Время начала производства | C15: Время окончания производства | D15: Время работы смены | E15: Плановая производительность | F15: Приведенное продуктивное время | G15: Эффективность от паспортной скорости % | H15: Вычитаемые простои (плановые, общезаводские) | I15: Условные простои (Необоснованные потери), мин | J15: Расчетная плановая производительность с учетом вычитаемых простоев | K15: Фактическая производительность за смену | L15: Выполнение сменного задания %, невыполнение -, перевыполнение + | N15: Вид Простоя | P15: Длительность, час | V15: Итого
N19: ПЛАНОВЫЕ | P19: =SUM(S47:S58) -> 0 | Q19: =SUM(S59:S69) -> 0 | R19: =SUM(S70:S80) -> 0 | S19: =SUM(S81:S91) -> 0 | T19: =SUM(S92:S102) -> 0 | U19: =SUM(S103:S113) -> 0 | V19: =P19+Q19+R19+S19+T19+U19 -> 0
D20: [мин] | E20: [шт./час] | F20: [мин] | H20: [мин] | J20: [шт./смену] | K20: [шт./смену] | L20: % | N20: ПРОИЗВОДСТВЕННЫЕ | P20: =SUM(T46:T57) -> 0 | Q20: =SUM(T58:T68) -> 0 | R20: =SUM(T69:T79) -> 0 | S20: =SUM(T80:T90) -> 0 | T20: =SUM(T91:T101) -> 0 | U20: =SUM(T102:T112) -> 0 | V20: =P20+Q20+R20+S20+T20+U20 -> 0
A21: =A37 -> 0 | D21: =(C21-B21+(C21<B21))*24*60 -> 0 | F21: =IF(E21=0,0,(F37/J3*60)) -> 0 | G21: =IF($K21=0,0,(K21*100)/(D21*$J$3/60)) -> 0 | H21: =P19+P26 -> 0 | I21: =D21-F21-P27 -> 0 | J21: =(D21-H21)/60*E21 -> 0 | K21: =F37 -> 0 | L21: =IF($K21=0,0,K21/J21) -> 0 | N21: ТЕХНИЧЕСКИЕ | P21: =SUM(U46:U57) -> 0 | Q21: =SUM(U58:U68) -> 0 | R21: =SUM(U69:U79) -> 0 | S21: =SUM(U80:U90) -> 0 | T21: =SUM(U91:U101) -> 0 | U21: =SUM(U102:U112) -> 0 | V21: =P21+Q21+R21+S21+T21+U21 -> 0
L22: =K21-J21 -> 0 | N22: ТЕХНОЛОГИЧЕСКИЕ | P22: =SUM(V46:V57) -> 0 | Q22: =SUM(V58:V68) -> 0 | R22: =SUM(V69:V79) -> 0 | S22: =SUM(V80:V90) -> 0 | T22: =SUM(V91:V101) -> 0 | U22: =SUM(V102:V112) -> 0 | V22: =P22+Q22+R22+S22+T22+U22 -> 0
A23: =A38 -> 0 | D23: =(C23-B23+(C23<B23))*24*60 -> 0 | F23: =IF(E23=0,0,(F38/J3*60)) -> 0 | G23: =IF($K23=0,0,(K23*100)/(D23*$J$3/60)) -> 0 | H23: =Q19+Q26 -> 0 | I23: =D23-F23-Q27 -> 0 | J23: =(D23-H23)/60*E23 -> 0 | K23: =F38 -> 0 | L23: =IF($K23=0,0,K23/J23) -> 0 | N23: ЛАБОРАТОРНЫЕ | P23: =SUM(W46:W57) -> 0 | Q23: =SUM(W58:W68) -> 0 | R23: =SUM(W69:W79) -> 0 | S23: =SUM(W80:W90) -> 0 | T23: =SUM(W91:W101) -> 0 | U23: =SUM(W102:W112) -> 0 | V23: =P23+Q23+R23+S23+T23+U23 -> 0
L24: =K23-J23 -> 0 | N24: СЫРЬЕВЫЕ | P24: =SUM(X46:X57) -> 0 | Q24: =SUM(X58:X68) -> 0 | R24: =SUM(X69:X79) -> 0 | S24: =SUM(X80:X90) -> 0 | T24: =SUM(X91:X101) -> 0 | U24: =SUM(X102:X112) -> 0 | V24: =P24+Q24+R24+S24+T24+U24 -> 0
A25: =A39 -> 0 | D25: =(C25-B25+(C25<B25))*24*60 -> 0 | F25: =IF(E25=0,0,(F39/J3*60)) -> 0 | G25: =IF($K25=0,0,(K25*100)/(D25*$J$3/60)) -> 0 | H25: =R19+R26 -> 0 | I25: =D25-F25-R27 -> 0 | J25: =(D25-H25)/60*E25 -> 0 | K25: =F39 -> 0 | L25: =IF($K25=0,0,K25/J25) -> 0 | N25: ЛОГИСТИЧЕСКИЕ | P25: =SUM(Y46:Y57) -> 0 | Q25: =SUM(Y58:Y68) -> 0 | R25: =SUM(Y69:Y79) -> 0 | S25: =SUM(Y80:Y90) -> 0 | T25: =SUM(Y91:Y101) -> 0 | U25: =SUM(Y102:Y112) -> 0 | V25: =P25+Q25+R25+S25+T25+U25 -> 0
L26: =K25-J25 -> 0 | N26: ОБЩЕЗАВОДСКИЕ | P26: =SUM(Z46:Z57) -> 0 | Q26: =SUM(Z58:Z68) -> 0 | R26: =SUM(Z69:Z79) -> 0 | S26: =SUM(Z80:Z90) -> 0 | T26: =SUM(Z91:Z101) -> 0 | U26: =SUM(Z102:Z112) -> 0 | V26: =P26+Q26+R26+S26+T26+U26 -> 0
A27: =A40 -> 0 | D27: =(C27-B27+(C27<B27))*24*60 -> 0 | F27: =IF(E27=0,0,(F40/J3*60)) -> 0 | G27: =IF($K27=0,0,(K27*100)/(D27*$J$3/60)) -> 0 | H27: =S19+S26 -> 0 | I27: =D27-F27-S27 -> 0 | J27: =(D27-H27)/60*E27 -> 0 | K27: =F40 -> 0 | L27: =IF($K27=0,0,K27/J27) -> 0 | N27: ИТОГО | P27: =SUM(P18:P26) -> 0 | Q27: =SUM(Q18:Q26) -> 0 | R27: =SUM(R18:R26) -> 0 | S27: =SUM(S18:S26) -> 0 | T27: =SUM(T18:T26) -> 0 | U27: =SUM(U18:U26) -> 0 | V27: =P27+Q27+R27+S27+T27+U27 -> 0
L28: =K27-J27 -> 0
A29: =A41 -> 0 | D29: =(C29-B29+(C29<B29))*24*60 -> 0 | F29: =IF(E29=0,0,(F41/J3*60)) -> 0 | G29: =IF($K29=0,0,(K29*100)/(D29*$J$3/60)) -> 0 | H29: =T19+T26 -> 0 | I29: =D29-F29-T27 -> 0 | J29: =(D29-H29)/60*E29 -> 0 | K29: =F41 -> 0 | L29: =IF($K29=0,0,K29/J29) -> 0
L30: =K29-J29 -> 0
A31: =A42 -> 0 | D31: =(C31-B31+(C31<B31))*24*60 -> 0 | F31: =IF(E31=0,0,(F42/J3*60)) -> 0 | G31: =IF($K31=0,0,(K31*100)/(D31*$J$3/60)) -> 0 | H31: =U19+U26 -> 0 | I31: =D31-F31-U27 -> 0 | J31: =(D31-H31)/60*E31 -> 0 | K31: =F42 -> 0 | L31: =IF($K31=0,0,K31/J31) -> 0
L32: =K31-J31 -> 0
A33: НАИМЕНОВАНИЕ И КОЛИЧЕСТВО ПРОИЗВЕДЕННОЙ ПРОДУКЦИИ (ЗАПОЛНЯЕТСЯ МАСТЕРОМ) | J33: Итого план | K33: Итого факт | L33: =IF($K34=0,0,K34/J34) -> 0
J34: =J21+J23+J25+J27+J29+J31 -> 0 | K34: =K21+K23+K25+K27+K29+K31 -> 0
A35: Наименование продукции, формат | F35: Выпуск по счетчику | G35: Сдано на склад гп | L35: Средний коэффициент по смене
K37: =G37 -> 0
K38: =G38 -> 0
K39: =G39 -> 0
K40: =G40 -> 0
K41: =G41 -> 0
K42: =G42 -> 0
A43: ИТОГО ПРОИЗВЕДЕНО ПРОДУКЦИИ | K43: =SUM(K37:K42) -> 0 | L43: =SUM(L38+L38) -> 0
A45: Наименование продукции, формат | B45: Время, час | D45: Объем производства, шт | E45: Автомат | F45: Описание простоя, причины | H45: Вид простоя | I45: Период простоя | K45: Время (мин) | L45: Корректирующие мероприятия | O45: Ответственный | P45: Сроки | Q45: Статус выполнения | S45: ПРОСТОИ
I46: Начало | J46: Конец | S46: ПЛАНОВЫЕ | T46: ПРОИЗВОДСТВЕННЫЕ | U46: ТЕХНИЧЕСКИЕ | V46: ТЕХНОЛОГИЧЕСКИЕ | W46: ЛАБОРАТОРНЫЕ | X46: СЫРЬЕВЫЕ | Y46: ЛОГИСТИЧЕСКИЕ | Z46: ОБЩЕЗАВОДСКИЕ
A47: =A37 -> 0 | B47: =B21 -> 0 | C47: =B47+1/24 -> 0.041666667 | K47: =(J47-I47+(J47<I47))*24*60 -> 0 | O47: =IF(H47=$V$5,$F$7,"") -> 0 | S47: =IF($H47="ПЛАНОВЫЕ",$K47,0) -> 0 | T47: =IF($H47="ПРОИЗВОДСТВЕННЫЕ",$K47,0) -> 0 | U47: =IF($H47="ТЕХНИЧЕСКИЕ",$K47,0) -> 0 | V47: =IF($H47="ТЕХНОЛОГИЧЕСКИЕ",$K47,0) -> 0 | W47: =IF($H47="ЛАБОРАТОРНЫЕ",$K47,0) -> 0 | X47: =IF($H47="СЫРЬЕВЫЕ",$K47,0) -> 0 | Y47: =IF($H47="ЛОГИСТИЧЕСКИЕ",$K47,0) -> 0 | Z47: =IF($H47="ОБЩЕЗАВОДСКИЕ",$K47,0) -> 0
B48: =C47 -> 0.041666667 | C48: =B48+1/24 -> 0.083333333 | K48: =(J48-I48+(J48<I48))*24*60 -> 0 | O48: =IF(H48=$V$5,$F$7,"") -> 0 | S48: =IF($H48="ПЛАНОВЫЕ",$K48,0) -> 0 | T48: =IF($H48="ПРОИЗВОДСТВЕННЫЕ",$K48,0) -> 0 | U48: =IF($H48="ТЕХНИЧЕСКИЕ",$K48,0) -> 0 | V48: =IF($H48="ТЕХНОЛОГИЧЕСКИЕ",$K48,0) -> 0 | W48: =IF($H48="ЛАБОРАТОРНЫЕ",$K48,0) -> 0 | X48: =IF($H48="СЫРЬЕВЫЕ",$K48,0) -> 0 | Y48: =IF($H48="ЛОГИСТИЧЕСКИЕ",$K48,0) -> 0 | Z48: =IF($H48="ОБЩЕЗАВОДСКИЕ",$K48,0) -> 0
B49: =C48 -> 0.083333333 | C49: =B49+1/24 -> 0.125 | K49: =(J49-I49+(J49<I49))*24*60 -> 0 | O49: =IF(H49=$V$5,$F$7,"") -> 0 | S49: =IF($H49="ПЛАНОВЫЕ",$K49,0) -> 0 | T49: =IF($H49="ПРОИЗВОДСТВЕННЫЕ",$K49,0) -> 0 | U49: =IF($H49="ТЕХНИЧЕСКИЕ",$K49,0) -> 0 | V49: =IF($H49="ТЕХНОЛОГИЧЕСКИЕ",$K49,0) -> 0 | W49: =IF($H49="ЛАБОРАТОРНЫЕ",$K49,0) -> 0 | X49: =IF($H49="СЫРЬЕВЫЕ",$K49,0) -> 0 | Y49: =IF($H49="ЛОГИСТИЧЕСКИЕ",$K49,0) -> 0 | Z49: =IF($H49="ОБЩЕЗАВОДСКИЕ",$K49,0) -> 0
...

Sheet 3
A1: Сменный отчет выпуска продукции
A2: Линия розлива № 6 - 3,0 л.
A3: Смена "Д" день с 08:00 по 20:00 | F3: Сутки план/факт | G3: =SUM(J21:J32)+SUM(J136:J147) -> 0 | H3: =SUM(K21:K32)+SUM(K136:K147) -> 0 | I3: паспортная скорость | J3: 650 | K3: Время смены | L3: 720
A4: Должность | F4: ФИО ответственного | I4: Рабочее место оператора | K4: ФИО оператора | N4: Поля для заполнения
A5: Начальник смены | I5: Розлив | O5: ФИКСИРОВАННЫЕ ПОЛЯ, НЕ ЗАПОЛНЯТЬ
A6: Мастер | I6: Упаковка
A7: Контролер | I7: Упаковка | O7: ПОЛЯ ДЛЯ ЗАПОЛНЕНИЯ МАСТЕРОМ
A8: Наладчик оборудования | I8: Упаковка
A9: Наладчик оборудования | I9: Упаковка
A14: ИТОГОВЫЙ РЕЗУЛЬТАТ РАБОТЫ СМЕНЫ (ВЫЧИСЛЯЕТСЯ АВТОМАТИЧЕСКИ) | N14: ПРОСТОИ (ВЫЧИСЛЯЕТСЯ АВТОМАТИЧЕСКИ)
A15: НАИМЕНОВАНИЕ НАПИТКА | B15: Время начала производства | C15: Время окончания производства | D15: Время работы смены | E15: Плановая производительность | F15: Приведенное продуктивное время | G15: Эффективность от паспортной скорости % | H15: Вычитаемые простои (плановые, общезаводские) | I15: Условные простои (Необоснованные потери), мин | J15: Расчетная плановая производительность с учетом вычитаемых простоев | K15: Фактическая производительность за смену | L15: Выполнение сменного задания %, невыполнение -, перевыполнение + | N15: Вид Простоя | P15: Длительность, час | V15: Итого
N19: ПЛАНОВЫЕ | P19: =SUM(S47:S58) -> 0 | Q19: =SUM(S59:S69) -> 0 | R19: =SUM(S70:S80) -> 0 | S19: =SUM(S81:S91) -> 0 | T19: =SUM(S92:S102) -> 0 | U19: =SUM(S103:S113) -> 0 | V19: =P19+Q19+R19+S19+T19+U19 -> 0
D20: [мин] | E20: [шт./час] | F20: [мин] | H20: [мин] | J20: [шт./смену] | K20: [шт./смену] | L20: % | N20: ПРОИЗВОДСТВЕННЫЕ | P20: =SUM(T46:T57) -> 0 | Q20: =SUM(T58:T68) -> 0 | R20: =SUM(T69:T79) -> 0 | S20: =SUM(T80:T90) -> 0 | T20: =SUM(T91:T101) -> 0 | U20: =SUM(T102:T112) -> 0 | V20: =P20+Q20+R20+S20+T20+U20 -> 0
A21: =A37 -> 0 | D21: =(C21-B21+(C21<B21))*24*60 -> 0 | F21: =IF(E21=0,0,(F37/J3*60)) -> 0 | G21: =IF($K21=0,0,(K21*100)/(D21*$J$3/60)) -> 0 | H21: =P19+P26 -> 0 | I21: =D21-F21-P27 -> 0 | J21: =(D21-H21)/60*E21 -> 0 | K21: =F37 -> 0 | L21: =IF($K21=0,0,K21/J21) -> 0 | N21: ТЕХНИЧЕСКИЕ | P21: =SUM(U46:U57) -> 0 | Q21: =SUM(U58:U68) -> 0 | R21: =SUM(U69:U79) -> 0 | S21: =SUM(U80:U90) -> 0 | T21: =SUM(U91:U101) -> 0 | U21: =SUM(U102:U112) -> 0 | V21: =P21+Q21+R21+S21+T21+U21 -> 0
L22: =K21-J21 -> 0 | N22: ТЕХНОЛОГИЧЕСКИЕ | P22: =SUM(V46:V57) -> 0 | Q22: =SUM(V58:V68) -> 0 | R22: =SUM(V69:V79) -> 0 | S22: =SUM(V80:V90) -> 0 | T22: =SUM(V91:V101) -> 0 | U22: =SUM(V102:V112) -> 0 | V22: =P22+Q22+R22+S22+T22+U22 -> 0
A23: =A38 -> 0 | D23: =(C23-B23+(C23<B23))*24*60 -> 0 | F23: =IF(E23=0,0,(F38/J3*60)) -> 0 | G23: =IF($K23=0,0,(K23*100)/(D23*$J$3/60)) -> 0 | H23: =Q19+Q26 -> 0 | I23: =D23-F23-Q27 -> 0 | J23: =(D23-H23)/60*E23 -> 0 | K23: =F38 -> 0 | L23: =IF($K23=0,0,K23/J23) -> 0 | N23: ЛАБОРАТОРНЫЕ | P23: =SUM(W46:W57) -> 0 | Q23: =SUM(W58:W68) -> 0 | R23: =SUM(W69:W79) -> 0 | S23: =SUM(W80:W90) -> 0 | T23: =SUM(W91:W101) -> 0 | U23: =SUM(W102:W112) -> 0 | V23: =P23+Q23+R23+S23+T23+U23 -> 0
L24: =K23-J23 -> 0 | N24: СЫРЬЕВЫЕ | P24: =SUM(X46:X57) -> 0 | Q24: =SUM(X58:X68) -> 0 | R24: =SUM(X69:X79) -> 0 | S24: =SUM(X80:X90) -> 0 | T24: =SUM(X91:X101) -> 0 | U24: =SUM(X102:X112) -> 0 | V24: =P24+Q24+R24+S24+T24+U24 -> 0
A25: =A39 -> 0 | D25: =(C25-B25+(C25<B25))*24*60 -> 0 | F25: =IF(E25=0,0,(F39/J3*60)) -> 0 | G25: =IF($K25=0,0,(K25*100)/(D25*$J$3/60)) -> 0 | H25: =R19+R26 -> 0 | I25: =D25-F25-R27 -> 0 | J25: =(D25-H25)/60*E25 -> 0 | K25: =F39 -> 0 | L25: =IF($K25=0,0,K25/J25) -> 0 | N25: ЛОГИСТИЧЕСКИЕ | P25: =SUM(Y46:Y57) -> 0 | Q25: =SUM(Y58:Y68) -> 0 | R25: =SUM(Y69:Y79) -> 0 | S25: =SUM(Y80:Y90) -> 0 | T25: =SUM(Y91:Y101) -> 0 | U25: =SUM(Y102:Y112) -> 0 | V25: =P25+Q25+R25+S25+T25+U25 -> 0
L26: =K25-J25 -> 0 | N26: ОБЩЕЗАВОДСКИЕ | P26: =SUM(Z46:Z57) -> 0 | Q26: =SUM(Z58:Z68) -> 0 | R26: =SUM(Z69:Z79) -> 0 | S26: =SUM(Z80:Z90) -> 0 | T26: =SUM(Z91:Z101) -> 0 | U26: =SUM(Z102:Z112) -> 0 | V26: =P26+Q26+R26+S26+T26+U26 -> 0
A27: =A40 -> 0 | D27: =(C27-B27+(C27<B27))*24*60 -> 0 | F27: =IF(E27=0,0,(F40/J3*60)) -> 0 | G27: =IF($K27=0,0,(K27*100)/(D27*$J$3/60)) -> 0 | H27: =S19+S26 -> 0 | I27: =D27-F27-S27 -> 0 | J27: =(D27-H27)/60*E27 -> 0 | K27: =F40 -> 0 | L27: =IF($K27=0,0,K27/J27) -> 0 | N27: ИТОГО | P27: =SUM(P18:P26) -> 0 | Q27: =SUM(Q18:Q26) -> 0 | R27: =SUM(R18:R26) -> 0 | S27: =SUM(S18:S26) -> 0 | T27: =SUM(T18:T26) -> 0 | U27: =SUM(U18:U26) -> 0 | V27: =P27+Q27+R27+S27+T27+U27 -> 0
L28: =K27-J27 -> 0
A29: =A41 -> 0 | D29: =(C29-B29+(C29<B29))*24*60 -> 0 | F29: =IF(E29=0,0,(F41/J3*60)) -> 0 | G29: =IF($K29=0,0,(K29*100)/(D29*$J$3/60)) -> 0 | H29: =T19+T26 -> 0 | I29: =D29-F29-T27 -> 0 | J29: =(D29-H29)/60*E29 -> 0 | K29: =F41 -> 0 | L29: =IF($K29=0,0,K29/J29) -> 0
L30: =K29-J29 -> 0
A31: =A42 -> 0 | D31: =(C31-B31+(C31<B31))*24*60 -> 0 | F31: =IF(E31=0,0,(F42/J3*60)) -> 0 | G31: =IF($K31=0,0,(K31*100)/(D31*$J$3/60)) -> 0 | H31: =U19+U26 -> 0 | I31: =D31-F31-U27 -> 0 | J31: =(D31-H31)/60*E31 -> 0 | K31: =F42 -> 0 | L31: =IF($K31=0,0,K31/J31) -> 0
L32: =K31-J31 -> 0
A33: НАИМЕНОВАНИЕ И КОЛИЧЕСТВО ПРОИЗВЕДЕННОЙ ПРОДУКЦИИ (ЗАПОЛНЯЕТСЯ МАСТЕРОМ) | J33: Итого план | K33: Итого факт | L33: =IF($K34=0,0,K34/J34) -> 0
J34: =J21+J23+J25+J27+J29+J31 -> 0 | K34: =K21+K23+K25+K27+K29+K31 -> 0
A35: Наименование продукции, формат | F35: Выпуск по счетчику | G35: Сдано на склад гп | L35: Средний коэффициент по смене
K37: =G37 -> 0
K38: =G38 -> 0
K39: =G39 -> 0
K40: =G40 -> 0
K41: =G41 -> 0
K42: =G42 -> 0
A43: ИТОГО ПРОИЗВЕДЕНО ПРОДУКЦИИ | K43: =SUM(K37:K42) -> 0 | L43: =SUM(L38+L38) -> 0
A45: Наименование продукции, формат | B45: Время, час | D45: Объем производства, шт | E45: Автомат | F45: Описание простоя, причины | H45: Вид простоя | I45: Период простоя | K45: Время (мин) | L45: Корректирующие мероприятия | O45: Ответственный | P45: Сроки | Q45: Статус выполнения | S45: ПРОСТОИ
I46: Начало | J46: Конец | S46: ПЛАНОВЫЕ | T46: ПРОИЗВОДСТВЕННЫЕ | U46: ТЕХНИЧЕСКИЕ | V46: ТЕХНОЛОГИЧЕСКИЕ | W46: ЛАБОРАТОРНЫЕ | X46: СЫРЬЕВЫЕ | Y46: ЛОГИСТИЧЕСКИЕ | Z46: ОБЩЕЗАВОДСКИЕ
A47: =A37 -> 0 | B47: =B21 -> 0 | C47: =B47+1/24 -> 0.041666667 | K47: =(J47-I47+(J47<I47))*24*60 -> 0 | O47: =IF(H47=$V$5,$F$7,"") -> 0 | S47: =IF($H47="ПЛАНОВЫЕ",$K47,0) -> 0 | T47: =IF($H47="ПРОИЗВОДСТВЕННЫЕ",$K47,0) -> 0 | U47: =IF($H47="ТЕХНИЧЕСКИЕ",$K47,0) -> 0 | V47: =IF($H47="ТЕХНОЛОГИЧЕСКИЕ",$K47,0) -> 0 | W47: =IF($H47="ЛАБОРАТОРНЫЕ",$K47,0) -> 0 | X47: =IF($H47="СЫРЬЕВЫЕ",$K47,0) -> 0 | Y47: =IF($H47="ЛОГИСТИЧЕСКИЕ",$K47,0) -> 0 | Z47: =IF($H47="ОБЩЕЗАВОДСКИЕ",$K47,0) -> 0
B48: =C47 -> 0.041666667 | C48: =B48+1/24 -> 0.083333333 | K48: =(J48-I48+(J48<I48))*24*60 -> 0 | O48: =IF(H48=$V$5,$F$7,"") -> 0 | S48: =IF($H48="ПЛАНОВЫЕ",$K48,0) -> 0 | T48: =IF($H48="ПРОИЗВОДСТВЕННЫЕ",$K48,0) -> 0 | U48: =IF($H48="ТЕХНИЧЕСКИЕ",$K48,0) -> 0 | V48: =IF($H48="ТЕХНОЛОГИЧЕСКИЕ",$K48,0) -> 0 | W48: =IF($H48="ЛАБОРАТОРНЫЕ",$K48,0) -> 0 | X48: =IF($H48="СЫРЬЕВЫЕ",$K48,0) -> 0 | Y48: =IF($H48="ЛОГИСТИЧЕСКИЕ",$K48,0) -> 0 | Z48: =IF($H48="ОБЩЕЗАВОДСКИЕ",$K48,0) -> 0
B49: =C48 -> 0.083333333 | C49: =B49+1/24 -> 0.125 | K49: =(J49-I49+(J49<I49))*24*60 -> 0 | O49: =IF(H49=$V$5,$F$7,"") -> 0 | S49: =IF($H49="ПЛАНОВЫЕ",$K49,0) -> 0 | T49: =IF($H49="ПРОИЗВОДСТВЕННЫЕ",$K49,0) -> 0 | U49: =IF($H49="ТЕХНИЧЕСКИЕ",$K49,0) -> 0 | V49: =IF($H49="ТЕХНОЛОГИЧЕСКИЕ",$K49,0) -> 0 | W49: =IF($H49="ЛАБОРАТОРНЫЕ",$K49,0) -> 0 | X49: =IF($H49="СЫРЬЕВЫЕ",$K49,0) -> 0 | Y49: =IF($H49="ЛОГИСТИЧЕСКИЕ",$K49,0) -> 0 | Z49: =IF($H49="ОБЩЕЗАВОДСКИЕ",$K49,0) -> 0
...

Sheet 4
A1: Сменный отчет выпуска продукции
A2: Линия розлива № 6 - 3,0 л.
A3: Смена "Д" день с 08:00 по 20:00 | F3: Сутки план/факт | G3: =SUM(J21:J32)+SUM(J136:J147) -> 0 | H3: =SUM(K21:K32)+SUM(K136:K147) -> 0 | I3: паспортная скорость | J3: 650 | K3: Время смены | L3: 720
A4: Должность | F4: ФИО ответственного | I4: Рабочее место оператора | K4: ФИО оператора | N4: Поля для заполнения
A5: Начальник смены | I5: Розлив | O5: ФИКСИРОВАННЫЕ ПОЛЯ, НЕ ЗАПОЛНЯТЬ
A6: Мастер | I6: Упаковка
A7: Контролер | I7: Упаковка | O7: ПОЛЯ ДЛЯ ЗАПОЛНЕНИЯ МАСТЕРОМ
A8: Наладчик оборудования | I8: Упаковка
A9: Наладчик оборудования | I9: Упаковка
A14: ИТОГОВЫЙ РЕЗУЛЬТАТ РАБОТЫ СМЕНЫ (ВЫЧИСЛЯЕТСЯ АВТОМАТИЧЕСКИ) | N14: ПРОСТОИ (ВЫЧИСЛЯЕТСЯ АВТОМАТИЧЕСКИ)
A15: НАИМЕНОВАНИЕ НАПИТКА | B15: Время начала производства | C15: Время окончания производства | D15: Время работы смены | E15: Плановая производительность | F15: Приведенное продуктивное время | G15: Эффективность от паспортной скорости % | H15: Вычитаемые простои (плановые, общезаводские) | I15: Условные простои (Необоснованные потери), мин | J15: Расчетная плановая производительность с учетом вычитаемых простоев | K15: Фактическая производительность за смену | L15: Выполнение сменного задания %, невыполнение -, перевыполнение + | N15: Вид Простоя | P15: Длительность, час | V15: Итого
N19: ПЛАНОВЫЕ | P19: =SUM(S47:S58) -> 0 | Q19: =SUM(S59:S69) -> 0 | R19: =SUM(S70:S80) -> 0 | S19: =SUM(S81:S91) -> 0 | T19: =SUM(S92:S102) -> 0 | U19: =SUM(S103:S113) -> 0 | V19: =P19+Q19+R19+S19+T19+U19 -> 0
D20: [мин] | E20: [шт./час] | F20: [мин] | H20: [мин] | J20: [шт./смену] | K20: [шт./смену] | L20: % | N20: ПРОИЗВОДСТВЕННЫЕ | P20: =SUM(T46:T57) -> 0 | Q20: =SUM(T58:T68) -> 0 | R20: =SUM(T69:T79) -> 0 | S20: =SUM(T80:T90) -> 0 | T20: =SUM(T91:T101) -> 0 | U20: =SUM(T102:T112) -> 0 | V20: =P20+Q20+R20+S20+T20+U20 -> 0
A21: =A37 -> 0 | D21: =(C21-B21+(C21<B21))*24*60 -> 0 | F21: =IF(E21=0,0,(F37/J3*60)) -> 0 | G21: =IF($K21=0,0,(K21*100)/(D21*$J$3/60)) -> 0 | H21: =P19+P26 -> 0 | I21: =D21-F21-P27 -> 0 | J21: =(D21-H21)/60*E21 -> 0 | K21: =F37 -> 0 | L21: =IF($K21=0,0,K21/J21) -> 0 | N21: ТЕХНИЧЕСКИЕ | P21: =SUM(U46:U57) -> 0 | Q21: =SUM(U58:U68) -> 0 | R21: =SUM(U69:U79) -> 0 | S21: =SUM(U80:U90) -> 0 | T21: =SUM(U91:U101) -> 0 | U21: =SUM(U102:U112) -> 0 | V21: =P21+Q21+R21+S21+T21+U21 -> 0
L22: =K21-J21 -> 0 | N22: ТЕХНОЛОГИЧЕСКИЕ | P22: =SUM(V46:V57) -> 0 | Q22: =SUM(V58:V68) -> 0 | R22: =SUM(V69:V79) -> 0 | S22: =SUM(V80:V90) -> 0 | T22: =SUM(V91:V101) -> 0 | U22: =SUM(V102:V112) -> 0 | V22: =P22+Q22+R22+S22+T22+U22 -> 0
A23: =A38 -> 0 | D23: =(C23-B23+(C23<B23))*24*60 -> 0 | F23: =IF(E23=0,0,(F38/J3*60)) -> 0 | G23: =IF($K23=0,0,(K23*100)/(D23*$J$3/60)) -> 0 | H23: =Q19+Q26 -> 0 | I23: =D23-F23-Q27 -> 0 | J23: =(D23-H23)/60*E23 -> 0 | K23: =F38 -> 0 | L23: =IF($K23=0,0,K23/J23) -> 0 | N23: ЛАБОРАТОРНЫЕ | P23: =SUM(W46:W57) -> 0 | Q23: =SUM(W58:W68) -> 0 | R23: =SUM(W69:W79) -> 0 | S23: =SUM(W80:W90) -> 0 | T23: =SUM(W91:W101) -> 0 | U23: =SUM(W102:W112) -> 0 | V23: =P23+Q23+R23+S23+T23+U23 -> 0
L24: =K23-J23 -> 0 | N24: СЫРЬЕВЫЕ | P24: =SUM(X46:X57) -> 0 | Q24: =SUM(X58:X68) -> 0 | R24: =SUM(X69:X79) -> 0 | S24: =SUM(X80:X90) -> 0 | T24: =SUM(X91:X101) -> 0 | U24: =SUM(X102:X112) -> 0 | V24: =P24+Q24+R24+S24+T24+U24 -> 0
A25: =A39 -> 0 | D25: =(C25-B25+(C25<B25))*24*60 -> 0 | F25: =IF(E25=0,0,(F39/J3*60)) -> 0 | G25: =IF($K25=0,0,(K25*100)/(D25*$J$3/60)) -> 0 | H25: =R19+R26 -> 0 | I25: =D25-F25-R27 -> 0 | J25: =(D25-H25)/60*E25 -> 0 | K25: =F39 -> 0 | L25: =IF($K25=0,0,K25/J25) -> 0 | N25: ЛОГИСТИЧЕСКИЕ | P25: =SUM(Y46:Y57) -> 0 | Q25: =SUM(Y58:Y68) -> 0 | R25: =SUM(Y69:Y79) -> 0 | S25: =SUM(Y80:Y90) -> 0 | T25: =SUM(Y91:Y101) -> 0 | U25: =SUM(Y102:Y112) -> 0 | V25: =P25+Q25+R25+S25+T25+U25 -> 0
L26: =K25-J25 -> 0 | N26: ОБЩЕЗАВОДСКИЕ | P26: =SUM(Z46:Z57) -> 0 | Q26: =SUM(Z58:Z68) -> 0 | R26: =SUM(Z69:Z79) -> 0 | S26: =SUM(Z80:Z90) -> 0 | T26: =SUM(Z91:Z101) -> 0 | U26: =SUM(Z102:Z112) -> 0 | V26: =P26+Q26+R26+S26+T26+U26 -> 0
A27: =A40 -> 0 | D27: =(C27-B27+(C27<B27))*24*60 -> 0 | F27: =IF(E27=0,0,(F40/J3*60)) -> 0 | G27: =IF($K27=0,0,(K27*100)/(D27*$J$3/60)) -> 0 | H27: =S19+S26 -> 0 | I27: =D27-F27-S27 -> 0 | J27: =(D27-H27)/60*E27 -> 0 | K27: =F40 -> 0 | L27: =IF($K27=0,0,K27/J27) -> 0 | N27: ИТОГО | P27: =SUM(P18:P26) -> 0 | Q27: =SUM(Q18:Q26) -> 0 | R27: =SUM(R18:R26) -> 0 | S27: =SUM(S18:S26) -> 0 | T27: =SUM(T18:T26) -> 0 | U27: =SUM(U18:U26) -> 0 | V27: =P27+Q27+R27+S27+T27+U27 -> 0
L28: =K27-J27 -> 0
A29: =A41 -> 0 | D29: =(C29-B29+(C29<B29))*24*60 -> 0 | F29: =IF(E29=0,0,(F41/J3*60)) -> 0 | G29: =IF($K29=0,0,(K29*100)/(D29*$J$3/60)) -> 0 | H29: =T19+T26 -> 0 | I29: =D29-F29-T27 -> 0 | J29: =(D29-H29)/60*E29 -> 0 | K29: =F41 -> 0 | L29: =IF($K29=0,0,K29/J29) -> 0
L30: =K29-J29 -> 0
A31: =A42 -> 0 | D31: =(C31-B31+(C31<B31))*24*60 -> 0 | F31: =IF(E31=0,0,(F42/J3*60)) -> 0 | G31: =IF($K31=0,0,(K31*100)/(D31*$J$3/60)) -> 0 | H31: =U19+U26 -> 0 | I31: =D31-F31-U27 -> 0 | J31: =(D31-H31)/60*E31 -> 0 | K31: =F42 -> 0 | L31: =IF($K31=0,0,K31/J31) -> 0
L32: =K31-J31 -> 0
A33: НАИМЕНОВАНИЕ И КОЛИЧЕСТВО ПРОИЗВЕДЕННОЙ ПРОДУКЦИИ (ЗАПОЛНЯЕТСЯ МАСТЕРОМ) | J33: Итого план | K33: Итого факт | L33: =IF($K34=0,0,K34/J34) -> 0
J34: =J21+J23+J25+J27+J29+J31 -> 0 | K34: =K21+K23+K25+K27+K29+K31 -> 0
A35: Наименование продукции, формат | F35: Выпуск по счетчику | G35: Сдано на склад гп | L35: Средний коэффициент по смене
K37: =G37 -> 0
K38: =G38 -> 0
K39: =G39 -> 0
K40: =G40 -> 0
K41: =G41 -> 0
K42: =G42 -> 0
A43: ИТОГО ПРОИЗВЕДЕНО ПРОДУКЦИИ | K43: =SUM(K37:K42) -> 0 | L43: =SUM(L38+L38) -> 0
A45: Наименование продукции, формат | B45: Время, час | D45: Объем производства, шт | E45: Автомат | F45: Описание простоя, причины | H45: Вид простоя | I45: Период простоя | K45: Время (мин) | L45: Корректирующие мероприятия | O45: Ответственный | P45: Сроки | Q45: Статус выполнения | S45: ПРОСТОИ
I46: Начало | J46: Конец | S46: ПЛАНОВЫЕ | T46: ПРОИЗВОДСТВЕННЫЕ | U46: ТЕХНИЧЕСКИЕ | V46: ТЕХНОЛОГИЧЕСКИЕ | W46: ЛАБОРАТОРНЫЕ | X46: СЫРЬЕВЫЕ | Y46: ЛОГИСТИЧЕСКИЕ | Z46: ОБЩЕЗАВОДСКИЕ
A47: =A37 -> 0 | B47: =B21 -> 0 | C47: =B47+1/24 -> 0.041666667 | K47: =(J47-I47+(J47<I47))*24*60 -> 0 | O47: =IF(H47=$V$5,$F$7,"") -> 0 | S47: =IF($H47="ПЛАНОВЫЕ",$K47,0) -> 0 | T47: =IF($H47="ПРОИЗВОДСТВЕННЫЕ",$K47,0) -> 0 | U47: =IF($H47="ТЕХНИЧЕСКИЕ",$K47,0) -> 0 | V47: =IF($H47="ТЕХНОЛОГИЧЕСКИЕ",$K47,0) -> 0 | W47: =IF($H47="ЛАБОРАТОРНЫЕ",$K47,0) -> 0 | X47: =IF($H47="СЫРЬЕВЫЕ",$K47,0) -> 0 | Y47: =IF($H47="ЛОГИСТИЧЕСКИЕ",$K47,0) -> 0 | Z47: =IF($H47="ОБЩЕЗАВОДСКИЕ",$K47,0) -> 0
B48: =C47 -> 0.041666667 | C48: =B48+1/24 -> 0.083333333 | K48: =(J48-I48+(J48<I48))*24*60 -> 0 | O48: =IF(H48=$V$5,$F$7,"") -> 0 | S48: =IF($H48="ПЛАНОВЫЕ",$K48,0) -> 0 | T48: =IF($H48="ПРОИЗВОДСТВЕННЫЕ",$K48,0) -> 0 | U48: =IF($H48="ТЕХНИЧЕСКИЕ",$K48,0) -> 0 | V48: =IF($H48="ТЕХНОЛОГИЧЕСКИЕ",$K48,0) -> 0 | W48: =IF($H48="ЛАБОРАТОРНЫЕ",$K48,0) -> 0 | X48: =IF($H48="СЫРЬЕВЫЕ",$K48,0) -> 0 | Y48: =IF($H48="ЛОГИСТИЧЕСКИЕ",$K48,0) -> 0 | Z48: =IF($H48="ОБЩЕЗАВОДСКИЕ",$K48,0) -> 0
B49: =C48 -> 0.083333333 | C49: =B49+1/24 -> 0.125 | K49: =(J49-I49+(J49<I49))*24*60 -> 0 | O49: =IF(H49=$V$5,$F$7,"") -> 0 | S49: =IF($H49="ПЛАНОВЫЕ",$K49,0) -> 0 | T49: =IF($H49="ПРОИЗВОДСТВЕННЫЕ",$K49,0) -> 0 | U49: =IF($H49="ТЕХНИЧЕСКИЕ",$K49,0) -> 0 | V49: =IF($H49="ТЕХНОЛОГИЧЕСКИЕ",$K49,0) -> 0 | W49: =IF($H49="ЛАБОРАТОРНЫЕ",$K49,0) -> 0 | X49: =IF($H49="СЫРЬЕВЫЕ",$K49,0) -> 0 | Y49: =IF($H49="ЛОГИСТИЧЕСКИЕ",$K49,0) -> 0 | Z49: =IF($H49="ОБЩЕЗАВОДСКИЕ",$K49,0) -> 0
...

Sheet 5
A1: Сменный отчет выпуска продукции
A2: Линия розлива № 6 - 3,0 л.
A3: Смена "Д" день с 08:00 по 20:00 | F3: Сутки план/факт | G3: =SUM(J21:J32)+SUM(J136:J147) -> 0 | H3: =SUM(K21:K32)+SUM(K136:K147) -> 0 | I3: паспортная скорость | J3: 650 | K3: Время смены | L3: 720
A4: Должность | F4: ФИО ответственного | I4: Рабочее место оператора | K4: ФИО оператора | N4: Поля для заполнения
A5: Начальник смены | I5: Розлив | O5: ФИКСИРОВАННЫЕ ПОЛЯ, НЕ ЗАПОЛНЯТЬ
A6: Мастер | I6: Упаковка
A7: Контролер | I7: Упаковка | O7: ПОЛЯ ДЛЯ ЗАПОЛНЕНИЯ МАСТЕРОМ
A8: Наладчик оборудования | I8: Упаковка
A9: Наладчик оборудования | I9: Упаковка
A14: ИТОГОВЫЙ РЕЗУЛЬТАТ РАБОТЫ СМЕНЫ (ВЫЧИСЛЯЕТСЯ АВТОМАТИЧЕСКИ) | N14: ПРОСТОИ (ВЫЧИСЛЯЕТСЯ АВТОМАТИЧЕСКИ)
A15: НАИМЕНОВАНИЕ НАПИТКА | B15: Время начала производства | C15: Время окончания производства | D15: Время работы смены | E15: Плановая производительность | F15: Приведенное продуктивное время | G15: Эффективность от паспортной скорости % | H15: Вычитаемые простои (плановые, общезаводские) | I15: Условные простои (Необоснованные потери), мин | J15: Расчетная плановая производительность с учетом вычитаемых простоев | K15: Фактическая производительность за смену | L15: Выполнение сменного задания %, невыполнение -, перевыполнение + | N15: Вид Простоя | P15: Длительность, час | V15: Итого
N19: ПЛАНОВЫЕ | P19: =SUM(S47:S58) -> 0 | Q19: =SUM(S59:S69) -> 0 | R19: =SUM(S70:S80) -> 0 | S19: =SUM(S81:S91) -> 0 | T19: =SUM(S92:S102) -> 0 | U19: =SUM(S103:S113) -> 0 | V19: =P19+Q19+R19+S19+T19+U19 -> 0
D20: [мин] | E20: [шт./час] | F20: [мин] | H20: [мин] | J20: [шт./смену] | K20: [шт./смену] | L20: % | N20: ПРОИЗВОДСТВЕННЫЕ | P20: =SUM(T46:T57) -> 0 | Q20: =SUM(T58:T68) -> 0 | R20: =SUM(T69:T79) -> 0 | S20: =SUM(T80:T90) -> 0 | T20: =SUM(T91:T101) -> 0 | U20: =SUM(T102:T112) -> 0 | V20: =P20+Q20+R20+S20+T20+U20 -> 0
A21: =A37 -> 0 | D21: =(C21-B21+(C21<B21))*24*60 -> 0 | F21: =IF(E21=0,0,(F37/J3*60)) -> 0 | G21: =IF($K21=0,0,(K21*100)/(D21*$J$3/60)) -> 0 | H21: =P19+P26 -> 0 | I21: =D21-F21-P27 -> 0 | J21: =(D21-H21)/60*E21 -> 0 | K21: =F37 -> 0 | L21: =IF($K21=0,0,K21/J21) -> 0 | N21: ТЕХНИЧЕСКИЕ | P21: =SUM(U46:U57) -> 0 | Q21: =SUM(U58:U68) -> 0 | R21: =SUM(U69:U79) -> 0 | S21: =SUM(U80:U90) -> 0 | T21: =SUM(U91:U101) -> 0 | U21: =SUM(U102:U112) -> 0 | V21: =P21+Q21+R21+S21+T21+U21 -> 0
L22: =K21-J21 -> 0 | N22: ТЕХНОЛОГИЧЕСКИЕ | P22: =SUM(V46:V57) -> 0 | Q22: =SUM(V58:V68) -> 0 | R22: =SUM(V69:V79) -> 0 | S22: =SUM(V80:V90) -> 0 | T22: =SUM(V91:V101) -> 0 | U22: =SUM(V102:V112) -> 0 | V22: =P22+Q22+R22+S22+T22+U22 -> 0
A23: =A38 -> 0 | D23: =(C23-B23+(C23<B23))*24*60 -> 0 | F23: =IF(E23=0,0,(F38/J3*60)) -> 0 | G23: =IF($K23=0,0,(K23*100)/(D23*$J$3/60)) -> 0 | H23: =Q19+Q26 -> 0 | I23: =D23-F23-Q27 -> 0 | J23: =(D23-H23)/60*E23 -> 0 | K23: =F38 -> 0 | L23: =IF($K23=0,0,K23/J23) -> 0 | N23: ЛАБОРАТОРНЫЕ | P23: =SUM(W46:W57) -> 0 | Q23: =SUM(W58:W68) -> 0 | R23: =SUM(W69:W79) -> 0 | S23: =SUM(W80:W90) -> 0 | T23: =SUM(W91:W101) -> 0 | U23: =SUM(W102:W112) -> 0 | V23: =P23+Q23+R23+S23+T23+U23 -> 0
L24: =K23-J23 -> 0 | N24: СЫРЬЕВЫЕ | P24: =SUM(X46:X57) -> 0 | Q24: =SUM(X58:X68) -> 0 | R24: =SUM(X69:X79) -> 0 | S24: =SUM(X80:X90) -> 0 | T24: =SUM(X91:X101) -> 0 | U24: =SUM(X102:X112) -> 0 | V24: =P24+Q24+R24+S24+T24+U24 -> 0
A25: =A39 -> 0 | D25: =(C25-B25+(C25<B25))*24*60 -> 0 | F25: =IF(E25=0,0,(F39/J3*60)) -> 0 | G25: =IF($K25=0,0,(K25*100)/(D25*$J$3/60)) -> 0 | H25: =R19+R26 -> 0 | I25: =D25-F25-R27 -> 0 | J25: =(D25-H25)/60*E25 -> 0 | K25: =F39 -> 0 | L25: =IF($K25=0,0,K25/J25) -> 0 | N25: ЛОГИСТИЧЕСКИЕ | P25: =SUM(Y46:Y57) -> 0 | Q25: =SUM(Y58:Y68) -> 0 | R25: =SUM(Y69:Y79) -> 0 | S25: =SUM(Y80:Y90) -> 0 | T25: =SUM(Y91:Y101) -> 0 | U25: =SUM(Y102:Y112) -> 0 | V25: =P25+Q25+R25+S25+T25+U25 -> 0
L26: =K25-J25 -> 0 | N26: ОБЩЕЗАВОДСКИЕ | P26: =SUM(Z46:Z57) -> 0 | Q26: =SUM(Z58:Z68) -> 0 | R26: =SUM(Z69:Z79) -> 0 | S26: =SUM(Z80:Z90) -> 0 | T26: =SUM(Z91:Z101) -> 0 | U26: =SUM(Z102:Z112) -> 0 | V26: =P26+Q26+R26+S26+T26+U26 -> 0
A27: =A40 -> 0 | D27: =(C27-B27+(C27<B27))*24*60 -> 0 | F27: =IF(E27=0,0,(F40/J3*60)) -> 0 | G27: =IF($K27=0,0,(K27*100)/(D27*$J$3/60)) -> 0 | H27: =S19+S26 -> 0 | I27: =D27-F27-S27 -> 0 | J27: =(D27-H27)/60*E27 -> 0 | K27: =F40 -> 0 | L27: =IF($K27=0,0,K27/J27) -> 0 | N27: ИТОГО | P27: =SUM(P18:P26) -> 0 | Q27: =SUM(Q18:Q26) -> 0 | R27: =SUM(R18:R26) -> 0 | S27: =SUM(S18:S26) -> 0 | T27: =SUM(T18:T26) -> 0 | U27: =SUM(U18:U26) -> 0 | V27: =P27+Q27+R27+S27+T27+U27 -> 0
L28: =K27-J27 -> 0
A29: =A41 -> 0 | D29: =(C29-B29+(C29<B29))*24*60 -> 0 | F29: =IF(E29=0,0,(F41/J3*60)) -> 0 | G29: =IF($K29=0,0,(K29*100)/(D29*$J$3/60)) -> 0 | H29: =T19+T26 -> 0 | I29: =D29-F29-T27 -> 0 | J29: =(D29-H29)/60*E29 -> 0 | K29: =F41 -> 0 | L29: =IF($K29=0,0,K29/J29) -> 0
L30: =K29-J29 -> 0
